Workbook

Sheet QC rev00
M2: Data Solicitação | P2: Início do Serviço | U2: Razão Social
D3: =MAX(C:C) -> 0 | E3: =Insumos!$C$1 -> 0 | P3: Término do Serviço | U3: Fantasia
D4: =MATCH($D$3,$C$10:$C$120,) -> 1 | E4: =Orçamento!$J$2+1 -> 4534 | H4: REV.09-09-2025 | M4: Nome/Nº OBRA | U4: Contato
F5: ="ORÇAMENTO: "&$P$4&" ("&$T$4&")" -> ORÇAMENTO: () | M5: Eng. Responsável | U5: Telefone
F6: ="ORÇAMENTO: "&$P$4&" ("&$T$4&")" -> ORÇAMENTO: () | M6: Suprimentos Responsável | P6: Adriano Carvalho | U6: Email
M7: {=IF(SUM(IF(OR($O$2="",$P$4="",$P$5="",$P$6="",$I$141="",$I$142="",$I$139="",$T2="",$T3=""),1,0))+SUM(IF($Y$2:$BC$2<>"",IF($Y$3:$BC$8="",1)))>0, "Faltam Campos a serem preenchidos",IF('Solic. Contrato'!$P$18="VÍNCULOS NÃO INDICADOS / ERRO NA QUANTIDADE VINCULADA","Falta de vínculos PL",""))} -> Faltam Campos a serem preenchidos | U7: CNPJ/CPF | V7: Melhores Condições
F8: Ordem | G8: Código Insumo | H8: Descrição do Insumo | I8: Unidade | J8: QUANT. | K8: R$ UNIT. | L8: R$ TOTAL | M8: Insumo | N8: ESCOPO DOS SERVIÇOS | Q8: OBS. CONTRATOS | U8: Validade CND
M9: Orçado | N9: Cod. | O9: Descrição | Q9: %Mat. | R9: %Equip. | S9: %Ret. | T9: Unidade | U9: QUANT. | V9: Fornecedor | W9: R$ UNIT. | X9: R$ TOTAL | Y9: R$ UNIT. | Z9: R$ TOTAL | AA9: OBS | AB9: R$ UNIT. | AC9: R$ TOTAL | AD9: OBS | AE9: R$ UNIT. | AF9: R$ TOTAL | AG9: OBS | AH9: R$ UNIT. | AI9: R$ TOTAL | AJ9: OBS | AK9: R$ UNIT. | AL9: R$ TOTAL | AM9: OBS | AN9: R$ UNIT. | AO9: R$ TOTAL | AP9: OBS | AQ9: R$ UNIT. | AR9: R$ TOTAL | AS9: OBS | AT9: R$ UNIT. | AU9: R$ TOTAL | AV9: OBS | AW9: R$ UNIT. | AX9: R$ TOTAL | AY9: OBS | AZ9: R$ UNIT. | BA9: R$ TOTAL | BB9: OBS
B10: =IF(C10=0,"",MATCH(_xlfn.MINIFS(Y10:BC10,Y$9:BC$9,$Y$9,Y10:BC10,"<>0",Y10:BC10,"<>"""),Y10:BC10,)) | C10: =IF(AND(N10<>"",N10<>0),MAX($C$8:$C9)+1,0) -> 0 | D10: =IF($F10>$E$3,"",_xlfn.MAXIFS(OFFSET(Orçamento!$G$5,$E10-5,,$E$4-$E10+5,),OFFSET(Orçamento!$N$5,$E10-5,,$E$4-$E10+5,),$G10)+1-E10+5) | E10: =IF($F10>$E$3,"",_xlfn.IFNA(MATCH($G10,Orçamento!$N:$N,),"")) | F10: 1 | G10: =IF($F10>$E$3,"",INDEX(Insumos!$C:$C,MATCH($F10,Insumos!$B:$B,),1)) | H10: {=IF($E10="","",INDEX(Orçamento!$O:$O,$E10,1))} | I10: {=IF($E10="","",INDEX(Orçamento!$Q:$Q,$E10,1))} | J10: =IF($D10="",0,SUMIF(OFFSET(Orçamento!$N$5,$E10-5,,$D10,),$G10,OFFSET(Orçamento!$I$5,$E10-5,,$D10,))) -> 0 | K10: {=IF($E10="",0,INDEX(Orçamento!$S:$S,$E10,1))} -> 0 | L10: =J10*K10 -> 0 | M10: =N10 | N10: =G10 | V10: {=IF($C10=0,0,INDEX($X$2:$BC$2,1,$B10+1))} -> 0 | W10: {=IF($C10=0,0,INDEX($X10:$BC10,1,$B10+1))} -> 0 | X10: =W10*U10 -> 0 | Z10: =Y10*$U10 -> 0 | AC10: =AB10*$U10 -> 0 | AF10: =AE10*$U10 -> 0 | AI10: =AH10*$U10 -> 0 | AL10: =AK10*$U10 -> 0 | AO10: =AN10*$U10 -> 0 | AR10: =AQ10*$U10 -> 0 | AU10: =AT10*$U10 -> 0 | AX10: =AW10*$U10 -> 0 | BA10: =AZ10*$U10 -> 0
B11: =IF(C11=0,"",MATCH(_xlfn.MINIFS(Y11:BC11,Y$9:BC$9,$Y$9,Y11:BC11,"<>0",Y11:BC11,"<>"""),Y11:BC11,)) | C11: =IF(AND(N11<>"",N11<>0),MAX($C$8:$C10)+1,0) -> 0 | D11: =IF($F11>$E$3,"",_xlfn.MAXIFS(OFFSET(Orçamento!$G$5,$E11-5,,$E$4-$E11+5,),OFFSET(Orçamento!$N$5,$E11-5,,$E$4-$E11+5,),$G11)+1-E11+5) | E11: =IF($F11>$E$3,"",_xlfn.IFNA(MATCH($G11,Orçamento!$N:$N,),"")) | F11: {=OFFSET(F11,-1,,,)+1} -> 2 | G11: =IF($F11>$E$3,"",INDEX(Insumos!$C:$C,MATCH($F11,Insumos!$B:$B,),1)) | H11: {=IF($E11="","",INDEX(Orçamento!$O:$O,$E11,1))} | I11: {=IF($E11="","",INDEX(Orçamento!$Q:$Q,$E11,1))} | J11: =IF($D11="",0,SUMIF(OFFSET(Orçamento!$N$5,$E11-5,,$D11,),$G11,OFFSET(Orçamento!$I$5,$E11-5,,$D11,))) -> 0 | K11: {=IF($E11="",0,INDEX(Orçamento!$S:$S,$E11,1))} -> 0 | L11: =J11*K11 -> 0 | M11: =N11 | N11: =G11 | O11: =H11 | T11: =I11 | U11: =J11 -> 0 | V11: {=IF($C11=0,0,INDEX($X$2:$BC$2,1,$B11+1))} -> 0 | W11: {=IF($C11=0,0,INDEX($X11:$BC11,1,$B11+1))} -> 0 | X11: =W11*U11 -> 0 | Z11: =Y11*$U11 -> 0 | AC11: =AB11*$U11 -> 0 | AF11: =AE11*$U11 -> 0 | AI11: =AH11*$U11 -> 0 | AL11: =AK11*$U11 -> 0 | AO11: =AN11*$U11 -> 0 | AR11: =AQ11*$U11 -> 0 | AU11: =AT11*$U11 -> 0 | AX11: =AW11*$U11 -> 0 | BA11: =AZ11*$U11 -> 0
B12: =IF(C12=0,"",MATCH(_xlfn.MINIFS(Y12:BC12,Y$9:BC$9,$Y$9,Y12:BC12,"<>0",Y12:BC12,"<>"""),Y12:BC12,)) | C12: =IF(AND(N12<>"",N12<>0),MAX($C$8:$C11)+1,0) -> 0 | D12: =IF($F12>$E$3,"",_xlfn.MAXIFS(OFFSET(Orçamento!$G$5,$E12-5,,$E$4-$E12+5,),OFFSET(Orçamento!$N$5,$E12-5,,$E$4-$E12+5,),$G12)+1-E12+5) | E12: =IF($F12>$E$3,"",_xlfn.IFNA(MATCH($G12,Orçamento!$N:$N,),"")) | F12: {=OFFSET(F12,-1,,,)+1} -> 3 | G12: =IF($F12>$E$3,"",INDEX(Insumos!$C:$C,MATCH($F12,Insumos!$B:$B,),1)) | H12: {=IF($E12="","",INDEX(Orçamento!$O:$O,$E12,1))} | I12: {=IF($E12="","",INDEX(Orçamento!$Q:$Q,$E12,1))} | J12: =IF($D12="",0,SUMIF(OFFSET(Orçamento!$N$5,$E12-5,,$D12,),$G12,OFFSET(Orçamento!$I$5,$E12-5,,$D12,))) -> 0 | K12: {=IF($E12="",0,INDEX(Orçamento!$S:$S,$E12,1))} -> 0 | L12: =J12*K12 -> 0 | M12: =N12 | N12: =G12 | O12: =H12 | T12: =I12 | U12: =J12 -> 0 | V12: {=IF($C12=0,0,INDEX($X$2:$BC$2,1,$B12+1))} -> 0 | W12: {=IF($C12=0,0,INDEX($X12:$BC12,1,$B12+1))} -> 0 | X12: =W12*U12 -> 0 | Z12: =Y12*$U12 -> 0 | AC12: =AB12*$U12 -> 0 | AF12: =AE12*$U12 -> 0 | AI12: =AH12*$U12 -> 0 | AL12: =AK12*$U12 -> 0 | AO12: =AN12*$U12 -> 0 | AR12: =AQ12*$U12 -> 0 | AU12: =AT12*$U12 -> 0 | AX12: =AW12*$U12 -> 0 | BA12: =AZ12*$U12 -> 0
B13: =IF(C13=0,"",MATCH(_xlfn.MINIFS(Y13:BC13,Y$9:BC$9,$Y$9,Y13:BC13,"<>0",Y13:BC13,"<>"""),Y13:BC13,)) | C13: =IF(AND(N13<>"",N13<>0),MAX($C$8:$C12)+1,0) -> 0 | D13: =IF($F13>$E$3,"",_xlfn.MAXIFS(OFFSET(Orçamento!$G$5,$E13-5,,$E$4-$E13+5,),OFFSET(Orçamento!$N$5,$E13-5,,$E$4-$E13+5,),$G13)+1-E13+5) | E13: =IF($F13>$E$3,"",_xlfn.IFNA(MATCH($G13,Orçamento!$N:$N,),"")) | F13: {=OFFSET(F13,-1,,,)+1} -> 4 | G13: =IF($F13>$E$3,"",INDEX(Insumos!$C:$C,MATCH($F13,Insumos!$B:$B,),1)) | H13: {=IF($E13="","",INDEX(Orçamento!$O:$O,$E13,1))} | I13: {=IF($E13="","",INDEX(Orçamento!$Q:$Q,$E13,1))} | J13: =IF($D13="",0,SUMIF(OFFSET(Orçamento!$N$5,$E13-5,,$D13,),$G13,OFFSET(Orçamento!$I$5,$E13-5,,$D13,))) -> 0 | K13: {=IF($E13="",0,INDEX(Orçamento!$S:$S,$E13,1))} -> 0 | L13: =J13*K13 -> 0 | M13: =N13 | N13: =G13 | O13: =H13 | T13: =I13 | U13: =J13 -> 0 | V13: {=IF($C13=0,0,INDEX($X$2:$BC$2,1,$B13+1))} -> 0 | W13: {=IF($C13=0,0,INDEX($X13:$BC13,1,$B13+1))} -> 0 | X13: =W13*U13 -> 0 | Z13: =Y13*$U13 -> 0 | AC13: =AB13*$U13 -> 0 | AF13: =AE13*$U13 -> 0 | AI13: =AH13*$U13 -> 0 | AL13: =AK13*$U13 -> 0 | AO13: =AN13*$U13 -> 0 | AR13: =AQ13*$U13 -> 0 | AU13: =AT13*$U13 -> 0 | AX13: =AW13*$U13 -> 0 | BA13: =AZ13*$U13 -> 0
B14: =IF(C14=0,"",MATCH(_xlfn.MINIFS(Y14:BC14,Y$9:BC$9,$Y$9,Y14:BC14,"<>0",Y14:BC14,"<>"""),Y14:BC14,)) | C14: =IF(AND(N14<>"",N14<>0),MAX($C$8:$C13)+1,0) -> 0 | D14: =IF($F14>$E$3,"",_xlfn.MAXIFS(OFFSET(Orçamento!$G$5,$E14-5,,$E$4-$E14+5,),OFFSET(Orçamento!$N$5,$E14-5,,$E$4-$E14+5,),$G14)+1-E14+5) | E14: =IF($F14>$E$3,"",_xlfn.IFNA(MATCH($G14,Orçamento!$N:$N,),"")) | F14: {=OFFSET(F14,-1,,,)+1} -> 5 | G14: =IF($F14>$E$3,"",INDEX(Insumos!$C:$C,MATCH($F14,Insumos!$B:$B,),1)) | H14: {=IF($E14="","",INDEX(Orçamento!$O:$O,$E14,1))} | I14: {=IF($E14="","",INDEX(Orçamento!$Q:$Q,$E14,1))} | J14: =IF($D14="",0,SUMIF(OFFSET(Orçamento!$N$5,$E14-5,,$D14,),$G14,OFFSET(Orçamento!$I$5,$E14-5,,$D14,))) -> 0 | K14: {=IF($E14="",0,INDEX(Orçamento!$S:$S,$E14,1))} -> 0 | L14: =J14*K14 -> 0 | M14: =N14 | N14: =G14 | O14: =H14 | T14: =I14 | U14: =J14 -> 0 | V14: {=IF($C14=0,0,INDEX($X$2:$BC$2,1,$B14+1))} -> 0 | W14: {=IF($C14=0,0,INDEX($X14:$BC14,1,$B14+1))} -> 0 | X14: =W14*U14 -> 0 | Z14: =Y14*$U14 -> 0 | AC14: =AB14*$U14 -> 0 | AF14: =AE14*$U14 -> 0 | AI14: =AH14*$U14 -> 0 | AL14: =AK14*$U14 -> 0 | AO14: =AN14*$U14 -> 0 | AR14: =AQ14*$U14 -> 0 | AU14: =AT14*$U14 -> 0 | AX14: =AW14*$U14 -> 0 | BA14: =AZ14*$U14 -> 0
B15: =IF(C15=0,"",MATCH(_xlfn.MINIFS(Y15:BC15,Y$9:BC$9,$Y$9,Y15:BC15,"<>0",Y15:BC15,"<>"""),Y15:BC15,)) | C15: =IF(AND(N15<>"",N15<>0),MAX($C$8:$C14)+1,0) -> 0 | D15: =IF($F15>$E$3,"",_xlfn.MAXIFS(OFFSET(Orçamento!$G$5,$E15-5,,$E$4-$E15+5,),OFFSET(Orçamento!$N$5,$E15-5,,$E$4-$E15+5,),$G15)+1-E15+5) | E15: =IF($F15>$E$3,"",_xlfn.IFNA(MATCH($G15,Orçamento!$N:$N,),"")) | F15: {=OFFSET(F15,-1,,,)+1} -> 6 | G15: =IF($F15>$E$3,"",INDEX(Insumos!$C:$C,MATCH($F15,Insumos!$B:$B,),1)) | H15: {=IF($E15="","",INDEX(Orçamento!$O:$O,$E15,1))} | I15: {=IF($E15="","",INDEX(Orçamento!$Q:$Q,$E15,1))} | J15: =IF($D15="",0,SUMIF(OFFSET(Orçamento!$N$5,$E15-5,,$D15,),$G15,OFFSET(Orçamento!$I$5,$E15-5,,$D15,))) -> 0 | K15: {=IF($E15="",0,INDEX(Orçamento!$S:$S,$E15,1))} -> 0 | L15: =J15*K15 -> 0 | M15: =N15 | N15: =G15 | O15: =H15 | T15: =I15 | U15: =J15 -> 0 | V15: {=IF($C15=0,0,INDEX($X$2:$BC$2,1,$B15+1))} -> 0 | W15: {=IF($C15=0,0,INDEX($X15:$BC15,1,$B15+1))} -> 0 | X15: =W15*U15 -> 0 | Z15: =Y15*$U15 -> 0 | AC15: =AB15*$U15 -> 0 | AF15: =AE15*$U15 -> 0 | AI15: =AH15*$U15 -> 0 | AL15: =AK15*$U15 -> 0 | AO15: =AN15*$U15 -> 0 | AR15: =AQ15*$U15 -> 0 | AU15: =AT15*$U15 -> 0 | AX15: =AW15*$U15 -> 0 | BA15: =AZ15*$U15 -> 0
B16: =IF(C16=0,"",MATCH(_xlfn.MINIFS(Y16:BC16,Y$9:BC$9,$Y$9,Y16:BC16,"<>0",Y16:BC16,"<>"""),Y16:BC16,)) | C16: =IF(AND(N16<>"",N16<>0),MAX($C$8:$C15)+1,0) -> 0 | D16: =IF($F16>$E$3,"",_xlfn.MAXIFS(OFFSET(Orçamento!$G$5,$E16-5,,$E$4-$E16+5,),OFFSET(Orçamento!$N$5,$E16-5,,$E$4-$E16+5,),$G16)+1-E16+5) | E16: =IF($F16>$E$3,"",_xlfn.IFNA(MATCH($G16,Orçamento!$N:$N,),"")) | F16: {=OFFSET(F16,-1,,,)+1} -> 7 | G16: =IF($F16>$E$3,"",INDEX(Insumos!$C:$C,MATCH($F16,Insumos!$B:$B,),1)) | H16: {=IF($E16="","",INDEX(Orçamento!$O:$O,$E16,1))} | I16: {=IF($E16="","",INDEX(Orçamento!$Q:$Q,$E16,1))} | J16: =IF($D16="",0,SUMIF(OFFSET(Orçamento!$N$5,$E16-5,,$D16,),$G16,OFFSET(Orçamento!$I$5,$E16-5,,$D16,))) -> 0 | K16: {=IF($E16="",0,INDEX(Orçamento!$S:$S,$E16,1))} -> 0 | L16: =J16*K16 -> 0 | M16: =N16 | N16: =G16 | O16: =H16 | T16: =I16 | U16: =J16 -> 0 | V16: {=IF($C16=0,0,INDEX($X$2:$BC$2,1,$B16+1))} -> 0 | W16: {=IF($C16=0,0,INDEX($X16:$BC16,1,$B16+1))} -> 0 | X16: =W16*U16 -> 0 | Z16: =Y16*$U16 -> 0 | AC16: =AB16*$U16 -> 0 | AF16: =AE16*$U16 -> 0 | AI16: =AH16*$U16 -> 0 | AL16: =AK16*$U16 -> 0 | AO16: =AN16*$U16 -> 0 | AR16: =AQ16*$U16 -> 0 | AU16: =AT16*$U16 -> 0 | AX16: =AW16*$U16 -> 0 | BA16: =AZ16*$U16 -> 0
B17: =IF(C17=0,"",MATCH(_xlfn.MINIFS(Y17:BC17,Y$9:BC$9,$Y$9,Y17:BC17,"<>0",Y17:BC17,"<>"""),Y17:BC17,)) | C17: =IF(AND(N17<>"",N17<>0),MAX($C$8:$C16)+1,0) -> 0 | D17: =IF($F17>$E$3,"",_xlfn.MAXIFS(OFFSET(Orçamento!$G$5,$E17-5,,$E$4-$E17+5,),OFFSET(Orçamento!$N$5,$E17-5,,$E$4-$E17+5,),$G17)+1-E17+5) | E17: =IF($F17>$E$3,"",_xlfn.IFNA(MATCH($G17,Orçamento!$N:$N,),"")) | F17: {=OFFSET(F17,-1,,,)+1} -> 8 | G17: =IF($F17>$E$3,"",INDEX(Insumos!$C:$C,MATCH($F17,Insumos!$B:$B,),1)) | H17: {=IF($E17="","",INDEX(Orçamento!$O:$O,$E17,1))} | I17: {=IF($E17="","",INDEX(Orçamento!$Q:$Q,$E17,1))} | J17: =IF($D17="",0,SUMIF(OFFSET(Orçamento!$N$5,$E17-5,,$D17,),$G17,OFFSET(Orçamento!$I$5,$E17-5,,$D17,))) -> 0 | K17: {=IF($E17="",0,INDEX(Orçamento!$S:$S,$E17,1))} -> 0 | L17: =J17*K17 -> 0 | M17: =N17 | N17: =G17 | O17: =H17 | T17: =I17 | U17: =J17 -> 0 | V17: {=IF($C17=0,0,INDEX($X$2:$BC$2,1,$B17+1))} -> 0 | W17: {=IF($C17=0,0,INDEX($X17:$BC17,1,$B17+1))} -> 0 | X17: =W17*U17 -> 0 | Z17: =Y17*$U17 -> 0 | AC17: =AB17*$U17 -> 0 | AF17: =AE17*$U17 -> 0 | AI17: =AH17*$U17 -> 0 | AL17: =AK17*$U17 -> 0 | AO17: =AN17*$U17 -> 0 | AR17: =AQ17*$U17 -> 0 | AU17: =AT17*$U17 -> 0 | AX17: =AW17*$U17 -> 0 | BA17: =AZ17*$U17 -> 0
B18: =IF(C18=0,"",MATCH(_xlfn.MINIFS(Y18:BC18,Y$9:BC$9,$Y$9,Y18:BC18,"<>0",Y18:BC18,"<>"""),Y18:BC18,)) | C18: =IF(AND(N18<>"",N18<>0),MAX($C$8:$C17)+1,0) -> 0 | D18: =IF($F18>$E$3,"",_xlfn.MAXIFS(OFFSET(Orçamento!$G$5,$E18-5,,$E$4-$E18+5,),OFFSET(Orçamento!$N$5,$E18-5,,$E$4-$E18+5,),$G18)+1-E18+5) | E18: =IF($F18>$E$3,"",_xlfn.IFNA(MATCH($G18,Orçamento!$N:$N,),"")) | F18: {=OFFSET(F18,-1,,,)+1} -> 9 | G18: =IF($F18>$E$3,"",INDEX(Insumos!$C:$C,MATCH($F18,Insumos!$B:$B,),1)) | H18: {=IF($E18="","",INDEX(Orçamento!$O:$O,$E18,1))} | I18: {=IF($E18="","",INDEX(Orçamento!$Q:$Q,$E18,1))} | J18: =IF($D18="",0,SUMIF(OFFSET(Orçamento!$N$5,$E18-5,,$D18,),$G18,OFFSET(Orçamento!$I$5,$E18-5,,$D18,))) -> 0 | K18: {=IF($E18="",0,INDEX(Orçamento!$S:$S,$E18,1))} -> 0 | L18: =J18*K18 -> 0 | M18: =N18 | N18: =G18 | O18: =H18 | T18: =I18 | U18: =J18 -> 0 | V18: {=IF($C18=0,0,INDEX($X$2:$BC$2,1,$B18+1))} -> 0 | W18: {=IF($C18=0,0,INDEX($X18:$BC18,1,$B18+1))} -> 0 | X18: =W18*U18 -> 0 | Z18: =Y18*$U18 -> 0 | AC18: =AB18*$U18 -> 0 | AF18: =AE18*$U18 -> 0 | AI18: =AH18*$U18 -> 0 | AL18: =AK18*$U18 -> 0 | AO18: =AN18*$U18 -> 0 | AR18: =AQ18*$U18 -> 0 | AU18: =AT18*$U18 -> 0 | AX18: =AW18*$U18 -> 0 | BA18: =AZ18*$U18 -> 0
B19: =IF(C19=0,"",MATCH(_xlfn.MINIFS(Y19:BC19,Y$9:BC$9,$Y$9,Y19:BC19,"<>0",Y19:BC19,"<>"""),Y19:BC19,)) | C19: =IF(AND(N19<>"",N19<>0),MAX($C$8:$C18)+1,0) -> 0 | D19: =IF($F19>$E$3,"",_xlfn.MAXIFS(OFFSET(Orçamento!$G$5,$E19-5,,$E$4-$E19+5,),OFFSET(Orçamento!$N$5,$E19-5,,$E$4-$E19+5,),$G19)+1-E19+5) | E19: =IF($F19>$E$3,"",_xlfn.IFNA(MATCH($G19,Orçamento!$N:$N,),"")) | F19: {=OFFSET(F19,-1,,,)+1} -> 10 | G19: =IF($F19>$E$3,"",INDEX(Insumos!$C:$C,MATCH($F19,Insumos!$B:$B,),1)) | H19: {=IF($E19="","",INDEX(Orçamento!$O:$O,$E19,1))} | I19: {=IF($E19="","",INDEX(Orçamento!$Q:$Q,$E19,1))} | J19: =IF($D19="",0,SUMIF(OFFSET(Orçamento!$N$5,$E19-5,,$D19,),$G19,OFFSET(Orçamento!$I$5,$E19-5,,$D19,))) -> 0 | K19: {=IF($E19="",0,INDEX(Orçamento!$S:$S,$E19,1))} -> 0 | L19: =J19*K19 -> 0 | M19: =N19 | N19: =G19 | O19: =H19 | T19: =I19 | U19: =J19 -> 0 | V19: {=IF($C19=0,0,INDEX($X$2:$BC$2,1,$B19+1))} -> 0 | W19: {=IF($C19=0,0,INDEX($X19:$BC19,1,$B19+1))} -> 0 | X19: =W19*U19 -> 0 | Z19: =Y19*$U19 -> 0 | AC19: =AB19*$U19 -> 0 | AF19: =AE19*$U19 -> 0 | AI19: =AH19*$U19 -> 0 | AL19: =AK19*$U19 -> 0 | AO19: =AN19*$U19 -> 0 | AR19: =AQ19*$U19 -> 0 | AU19: =AT19*$U19 -> 0 | AX19: =AW19*$U19 -> 0 | BA19: =AZ19*$U19 -> 0
B20: =IF(C20=0,"",MATCH(_xlfn.MINIFS(Y20:BC20,Y$9:BC$9,$Y$9,Y20:BC20,"<>0",Y20:BC20,"<>"""),Y20:BC20,)) | C20: =IF(AND(N20<>"",N20<>0),MAX($C$8:$C19)+1,0) -> 0 | D20: =IF($F20>$E$3,"",_xlfn.MAXIFS(OFFSET(Orçamento!$G$5,$E20-5,,$E$4-$E20+5,),OFFSET(Orçamento!$N$5,$E20-5,,$E$4-$E20+5,),$G20)+1-E20+5) | E20: =IF($F20>$E$3,"",_xlfn.IFNA(MATCH($G20,Orçamento!$N:$N,),"")) | F20: {=OFFSET(F20,-1,,,)+1} -> 11 | G20: =IF($F20>$E$3,"",INDEX(Insumos!$C:$C,MATCH($F20,Insumos!$B:$B,),1)) | H20: {=IF($E20="","",INDEX(Orçamento!$O:$O,$E20,1))} | I20: {=IF($E20="","",INDEX(Orçamento!$Q:$Q,$E20,1))} | J20: =IF($D20="",0,SUMIF(OFFSET(Orçamento!$N$5,$E20-5,,$D20,),$G20,OFFSET(Orçamento!$I$5,$E20-5,,$D20,))) -> 0 | K20: {=IF($E20="",0,INDEX(Orçamento!$S:$S,$E20,1))} -> 0 | L20: =J20*K20 -> 0 | M20: =N20 | N20: =G20 | O20: =H20 | T20: =I20 | U20: =J20 -> 0 | V20: {=IF($C20=0,0,INDEX($X$2:$BC$2,1,$B20+1))} -> 0 | W20: {=IF($C20=0,0,INDEX($X20:$BC20,1,$B20+1))} -> 0 | X20: =W20*U20 -> 0 | Z20: =Y20*$U20 -> 0 | AC20: =AB20*$U20 -> 0 | AF20: =AE20*$U20 -> 0 | AI20: =AH20*$U20 -> 0 | AL20: =AK20*$U20 -> 0 | AO20: =AN20*$U20 -> 0 | AR20: =AQ20*$U20 -> 0 | AU20: =AT20*$U20 -> 0 | AX20: =AW20*$U20 -> 0 | BA20: =AZ20*$U20 -> 0
B21: =IF(C21=0,"",MATCH(_xlfn.MINIFS(Y21:BC21,Y$9:BC$9,$Y$9,Y21:BC21,"<>0",Y21:BC21,"<>"""),Y21:BC21,)) | C21: =IF(AND(N21<>"",N21<>0),MAX($C$8:$C20)+1,0) -> 0 | D21: =IF($F21>$E$3,"",_xlfn.MAXIFS(OFFSET(Orçamento!$G$5,$E21-5,,$E$4-$E21+5,),OFFSET(Orçamento!$N$5,$E21-5,,$E$4-$E21+5,),$G21)+1-E21+5) | E21: =IF($F21>$E$3,"",_xlfn.IFNA(MATCH($G21,Orçamento!$N:$N,),"")) | F21: {=OFFSET(F21,-1,,,)+1} -> 12 | G21: =IF($F21>$E$3,"",INDEX(Insumos!$C:$C,MATCH($F21,Insumos!$B:$B,),1)) | H21: {=IF($E21="","",INDEX(Orçamento!$O:$O,$E21,1))} | I21: {=IF($E21="","",INDEX(Orçamento!$Q:$Q,$E21,1))} | J21: =IF($D21="",0,SUMIF(OFFSET(Orçamento!$N$5,$E21-5,,$D21,),$G21,OFFSET(Orçamento!$I$5,$E21-5,,$D21,))) -> 0 | K21: {=IF($E21="",0,INDEX(Orçamento!$S:$S,$E21,1))} -> 0 | L21: =J21*K21 -> 0 | M21: =N21 | N21: =G21 | O21: =H21 | T21: =I21 | U21: =J21 -> 0 | V21: {=IF($C21=0,0,INDEX($X$2:$BC$2,1,$B21+1))} -> 0 | W21: {=IF($C21=0,0,INDEX($X21:$BC21,1,$B21+1))} -> 0 | X21: =W21*U21 -> 0 | Z21: =Y21*$U21 -> 0 | AC21: =AB21*$U21 -> 0 | AF21: =AE21*$U21 -> 0 | AI21: =AH21*$U21 -> 0 | AL21: =AK21*$U21 -> 0 | AO21: =AN21*$U21 -> 0 | AR21: =AQ21*$U21 -> 0 | AU21: =AT21*$U21 -> 0 | AX21: =AW21*$U21 -> 0 | BA21: =AZ21*$U21 -> 0
B22: =IF(C22=0,"",MATCH(_xlfn.MINIFS(Y22:BC22,Y$9:BC$9,$Y$9,Y22:BC22,"<>0",Y22:BC22,"<>"""),Y22:BC22,)) | C22: =IF(AND(N22<>"",N22<>0),MAX($C$8:$C21)+1,0) -> 0 | D22: =IF($F22>$E$3,"",_xlfn.MAXIFS(OFFSET(Orçamento!$G$5,$E22-5,,$E$4-$E22+5,),OFFSET(Orçamento!$N$5,$E22-5,,$E$4-$E22+5,),$G22)+1-E22+5) | E22: =IF($F22>$E$3,"",_xlfn.IFNA(MATCH($G22,Orçamento!$N:$N,),"")) | F22: {=OFFSET(F22,-1,,,)+1} -> 13 | G22: =IF($F22>$E$3,"",INDEX(Insumos!$C:$C,MATCH($F22,Insumos!$B:$B,),1)) | H22: {=IF($E22="","",INDEX(Orçamento!$O:$O,$E22,1))} | I22: {=IF($E22="","",INDEX(Orçamento!$Q:$Q,$E22,1))} | J22: =IF($D22="",0,SUMIF(OFFSET(Orçamento!$N$5,$E22-5,,$D22,),$G22,OFFSET(Orçamento!$I$5,$E22-5,,$D22,))) -> 0 | K22: {=IF($E22="",0,INDEX(Orçamento!$S:$S,$E22,1))} -> 0 | L22: =J22*K22 -> 0 | M22: =N22 | N22: =G22 | O22: =H22 | T22: =I22 | U22: =J22 -> 0 | V22: {=IF($C22=0,0,INDEX($X$2:$BC$2,1,$B22+1))} -> 0 | W22: {=IF($C22=0,0,INDEX($X22:$BC22,1,$B22+1))} -> 0 | X22: =W22*U22 -> 0 | Z22: =Y22*$U22 -> 0 | AC22: =AB22*$U22 -> 0 | AF22: =AE22*$U22 -> 0 | AI22: =AH22*$U22 -> 0 | AL22: =AK22*$U22 -> 0 | AO22: =AN22*$U22 -> 0 | AR22: =AQ22*$U22 -> 0 | AU22: =AT22*$U22 -> 0 | AX22: =AW22*$U22 -> 0 | BA22: =AZ22*$U22 -> 0
... B119: =IF(C119=0,"",MATCH(_xlfn.MINIFS(Y119:BC119,Y$9:BC$9,$Y$9,Y119:BC119,"<>0",Y119:BC119,"<>"""),Y119:BC119,)) | C119: =IF(AND(N119<>"",N119<>0),MAX($C$8:$C118)+1,0) -> 0 | D119: =IF($F119>$E$3,"",_xlfn.MAXIFS(OFFSET(Orçamento!$G$5,$E119-5,,$E$4-$E119+5,),OFFSET(Orçamento!$N$5,$E119-5,,$E$4-$E119+5,),$G119)+1-E119+5) | E119: =IF($F119>$E$3,"",_xlfn.IFNA(MATCH($G119,Orçamento!$N:$N,),"")) | F119: {=OFFSET(F119,-1,,,)+1} -> 110 | G119: =IF($F119>$E$3,"",INDEX(Insumos!$C:$C,MATCH($F119,Insumos!$B:$B,),1)) | H119: {=IF($E119="","",INDEX(Orçamento!$O:$O,$E119,1))} | I119: {=IF($E119="","",INDEX(Orçamento!$Q:$Q,$E119,1))} | J119: =IF($D119="",0,SUMIF(OFFSET(Orçamento!$N$5,$E119-5,,$D119,),$G119,OFFSET(Orçamento!$I$5,$E119-5,,$D119,))) -> 0 | K119: {=IF($E119="",0,INDEX(Orçamento!$S:$S,$E119,1))} -> 0 | L119: =J119*K119 -> 0 | M119: =N119 | N119: =G119 | O119: =H119 | T119: =I119 | U119: =J119 -> 0 | V119: {=IF($C119=0,0,INDEX($X$2:$BC$2,1,$B119+1))} -> 0 | W119: {=IF($C119=0,0,INDEX($X119:$BC119,1,$B119+1))} -> 0 | X119: =W119*U119 -> 0 | Z119: =Y119*$U119 -> 0 | AC119: =AB119*$U119 -> 0 | AF119: =AE119*$U119 -> 0 | AI119: =AH119*$U119 -> 0 | AL119: =AK119*$U119 -> 0 | AO119: =AN119*$U119 -> 0 | AR119: =AQ119*$U119 -> 0 | AU119: =AT119*$U119 -> 0 | AX119: =AW119*$U119 -> 0 | BA119: =AZ119*$U119 -> 0
M120: Total Orçado: | P120: =SUM(L10:L119) -> 0 | T120: R$ Total Equalizado rev00 | X120: =SUM(X10:X119) -> 0 | Z120: =SUM(Z10:Z119) -> 0 | AC120: =SUM(AC10:AC119) -> 0 | AF120: =SUM(AF10:AF119) -> 0 | AI120: =SUM(AI10:AI119) -> 0 | AL120: =SUM(AL10:AL119) -> 0 | AO120: =SUM(AO10:AO119) -> 0 | AR120: =SUM(AR10:AR119) -> 0 | AU120: =SUM(AU10:AU119) -> 0 | AX120: =SUM(AX10:AX119) -> 0 | BA120: =SUM(BA10:BA119) -> 0
F121: OBSERVAÇÕES DA ENGENHARIA / GERAL | M121: Verba Já Utilizada: | T121: R$ Total Equalizado rev01
M122: Acréscimos/Reduções: | T122: R$ Total Equalizado rev02
M123: Verba Disponível: | P123: =SUM(P120:P122) -> 0 | T123: Resultado QC / Orçamento | X123: =$P$123-X120 -> 0 | Y123: =IFERROR(Z123/$P$120,0) -> 0 | Z123: =$P$123-Z120 -> 0 | AB123: =IFERROR(AC123/$P$120,0) -> 0 | AC123: =$P$123-AC120 -> 0 | AE123: =IFERROR(AF123/$P$120,0) -> 0 | AF123: =$P$123-AF120 -> 0 | AH123: =IFERROR(AI123/$P$120,0) -> 0 | AI123: =$P$123-AI120 -> 0 | AK123: =IFERROR(AL123/$P$120,0) -> 0 | AL123: =$P$123-AL120 -> 0 | AN123: =IFERROR(AO123/$P$120,0) -> 0 | AO123: =$P$123-AO120 -> 0 | AQ123: =IFERROR(AR123/$P$120,0) -> 0 | AR123: =$P$123-AR120 -> 0 | AT123: =IFERROR(AU123/$P$120,0) -> 0 | AU123: =$P$123-AU120 -> 0 | AW123: =IFERROR(AX123/$P$120,0) -> 0 | AX123: =$P$123-AX120 -> 0 | AZ123: =IFERROR(BA123/$P$120,0) -> 0 | BA123: =$P$123-BA120 -> 0
N124: OBSERVAÇÕES SUPRIMENTOS | U124: Prazo de execução /Entrega
U127: Condição Pagamento
U130: Forma de Reajuste
U133: Observações
F139: Tipo de Contrato | U139: Pontos Positivos
F141: Empresa Vencendora | I141: 0
F142: Justificativa
U143: Pontos Negativos
F144: Aprovações
H146: ... | L146: GERENTE / COORDENADOR DE OBRA

Sheet Solic. Contrato
D2: =MAX(Orçamento!C:C) -> 0 | E2: ='QC rev00'!$D$3 -> 0 | F2: =Listas!$K$2 -> #REF! | I2: FORMULÁRIO DE SOLICITAÇÃO PARA GERAR CONTRATO DE SERVIÇOS E LOCAÇÃO DE EQUIPAMENTOS COM OPERAÇÃO | R2: REVISÃO: | T2: 1
D3: =MAX($D$22:$D$353)+10 -> 10 | E3: =Orçamento!J2+5 -> 4538 | F3: =Listas!$L$2 -> #REF! | R3: DATA: | T3: =IF($F$2=1,'QC rev00'!$O$2,IF($F$2=2,#REF!,#REF!)) -> #REF!
E5: =IFERROR(SEARCH("Com Fat Direto",I16,1),"X") -> X | F5: =F6*IF(E5="X",1,$K$17+$N$17) -> #REF! | G5: 1. INFORMAÇÕES GERAIS
E6: IM07922 | F6: {=_xlfn.IFNA(IF($F$2=1,OFFSET('QC rev00'!$U$120,,$F$3+1,,),IF($F$2=2,OFFSET(#REF!,,$F$3+1,,),OFFSET(#REF!,,$F$3+1,,))),0)} -> #REF! | G6: 1.1 DADOS INICIAIS
G7: OBRA: | H7: ='QC rev00'!$P$4 -> 0 | J7: ="Nº da Obra: "&'QC rev00'!$T$4 -> Nº da Obra: | K7: Nº da Solicitação de Cotação: | O7: SOLICITANTE: | P7: ='QC rev00'!$P$5 -> 0 | R7: VERBA ORÇAMENTÁRIA: | T7: =IF($F$2=1,'QC rev00'!$P$120,IF($F$2=2,#REF!,#REF!)) -> #REF!
G8: 1.2 OBJETO DO CONTRATO: | I8: ='QC rev00'!H2 -> 0
G9: 1.3 DADOS DO CONTRATADO
G10: Razão Social: | H10: {=IF($F$2=1,OFFSET('QC rev00'!$U$2,,$F$3,,),IF($F$2=2,OFFSET(#REF!,,$F$3,,),OFFSET(#REF!,,$F$3,,)))} -> #REF!
G11: CNPJ: | H11: {=IF($F$2=1,OFFSET('QC rev00'!$U$7,,$F$3,,),IF($F$2=2,OFFSET(#REF!,,$F$3,,),OFFSET(#REF!,,$F$3,,)))} -> #REF! | J11: TEL/CEL: | K11: {=IF($F$2=1,OFFSET('QC rev00'!$U$5,,$F$3,,),IF($F$2=2,OFFSET(#REF!,,$F$3,,),OFFSET(#REF!,,$F$3,,)))} -> #REF! | N11: E-MAIL: | O11: {=IF($F$2=1,OFFSET('QC rev00'!$U$6,,$F$3,,),IF($F$2=2,OFFSET(#REF!,,$F$3,,),OFFSET(#REF!,,$F$3,,)))} -> #REF! | R11: CONTATO: | S11: {=IF($F$2=1,OFFSET('QC rev00'!$U$4,,$F$3,,),IF($F$2=2,OFFSET(#REF!,,$F$3,,),OFFSET(#REF!,,$F$3,,)))} -> #REF!
G12: 1.4 DADOS DO 2º CONTRATADO (caso tenha faturamento por medição para mais de uma empresa)
G13: Razão Social:
G14: CNPJ: | J14: TEL/CEL: | N14: E-MAIL: | R14: CONTATO:
G16: 1.5 TIPO DE CONTRATO | I16: =IF($F$2=1,'QC rev00'!$I$139,IF($F$2=2,#REF!,#REF!)) -> #REF!
G17: 1.6 DISTRIBUIÇÃO E RETENÇÃO | I17: % DE DISTRIBUIÇÃO DO CONTRATO | J17: Material | K17: =IF($F$2=1,SUMPRODUCT(OFFSET('QC rev00'!$M$10:$M$119,$F25-1,9+$F$3,,),'QC rev00'!$Q$10:$Q$119),IF($F$2=2,SUMPRODUCT(OFFSET(#REF!,$F25-1,9+$F$3,,),#REF!),SUMPRODUCT(OFFSET(#REF!,$F25-1,9+$F$3,,),#REF!)))/$F$6 -> #REF! | L17: Equipamento | N17: =IF($F$2=1,SUMPRODUCT(OFFSET('QC rev00'!$M$10:$M$119,$F25-1,9+$F$3,,),'QC rev00'!$R$10:$R$119),IF($F$2=2,SUMPRODUCT(OFFSET(#REF!,$F25-1,9+$F$3,,),#REF!),SUMPRODUCT(OFFSET(#REF!,$F25-1,9+$F$3,,),#REF!)))/$F$6 -> #REF! | O17: MDO / Serviço | P17: =1-K17-N17 -> #REF!
G18: 1.7 VALIDADE DO CONTRATO | I18: DATA DE INÍCIO DO CONTRATO: | J18: =IF($F$2=1,'QC rev00'!$T$2,IF($F$2=2,#REF!,#REF!)) -> #REF! | K18: DATA DE TÉRMINO: | N18: =IF($F$2=1,'QC rev00'!$T$3,IF($F$2=2,#REF!,#REF!)) -> #REF! | P18: =IF(COUNTIF($C$23:$C$353,"X")>0,"VÍNCULOS NÃO INDICADOS / ERRO NA QUANTIDADE VINCULADA","")
G20: 2. ESPECIFICAÇÃO DOS SERVIÇOS CONTRATADO:
G21: COD. DO INSUMO | H21: DESCRIÇÃO | J21: Especificação | L21: % Retenção | M21: UNID. | N21: QUANT. | O21: R$ UNITÁRIO | P21: R$ TOTAL | Q21: Vínculos | R21: 1 | S21: =R21+1 -> 2 | T21: =S21+1 -> 3 | U21: =T21+1 -> 4 | V21: =U21+1 -> 5 | W21: =V21+1 -> 6 | X21: =W21+1 -> 7 | Y21: =X21+1 -> 8 | Z21: =Y21+1 -> 9 | ... AK21: =AJ21+1 -> 20
B23: =IF($F23>$E$2,0,IF(E23<>"",MATCH(F24&" - Mapa",Orçamento!J:J,),0)) -> 0 | C23: =IF($D23>1,_xlfn.MAXIFS(Orçamento!G:G,Orçamento!J:J,F24&" - Mapa")+6-B23,0) -> 0 | D23: =IF($F23>$E$2,0,IF($G23=$E$6,$D$2,IF(E23<>"",_xlfn.MAXIFS(Orçamento!E:E,Orçamento!J:J,F24&" - Mapa"),0))) -> 0 | E23: =IF(F24="","",_xlfn.IFNA(MATCH($F24,'QC rev00'!$G$10:$G$120,),"")) | F23: {=OFFSET(F23,-3,,,)+1} -> 1 | G23: {=IF($F23>$E$2,"",IF($F$2=1,INDEX('QC rev00'!$M$10:$T$120,$F25,2),IF($F$2=2,INDEX(#REF!,$F25,2),INDEX(#REF!,$F25,2))))} | H23: {=IF($F23>$E$2,"",IF($F$2=1,INDEX('QC rev00'!$M$10:$T$120,$F25,3),IF($F$2=2,INDEX(#REF!,$F25,3),INDEX(#REF!,$F25,3))))} | L23: {=IF($F23>$E$2,"",IF($F$2=1,INDEX('QC rev00'!$M$10:$T$120,$F25,7),IF($F$2=2,INDEX(#REF!,$F25,7),INDEX(#REF!,$F25,7))))} | M23: {=IF($F23>$E$2,"",IF($F$2=1,INDEX('QC rev00'!$M$10:$T$120,$F25,8),IF($F$2=2,INDEX(#REF!,$F25,8),INDEX(#REF!,$F25,8))))} | N23: {=IF($F23>$E$2,0,IF(_xlfn.IFNA(MATCH($G23,Listas!$E$4:$E$206,),0)>0,$F$5,IF($F$2=1,INDEX('QC rev00'!$M$10:$U$120,$F25,9),IF($F$2=2,INDEX(#REF!,$F25,9),INDEX(#REF!,$F25,9)))))} -> 0 | O23: {=IF($F23>$E$2,0,IF(_xlfn.IFNA(MATCH($G23,Listas!$E$4:$E$206,),0)>0,1,IF($H$10=0,0,IF($F$2=1,INDEX('QC rev00'!$M$10:$BC$120,$F25,9+$F$3),IF($F$2=2,INDEX(#REF!,$F25,9+$F$3),INDEX(#REF!,$F25,9+$F$3)))*IF($E$5="X",1,1-$B25-$C25))))} -> 0 | P23: =N23*O23 -> 0 | Q23: IP | R23: {=IF($D23=0,"",IF($G23=$E$6,INDEX(Orçamento!$U:$U,MATCH(R$21,Orçamento!$C:$C,),1),INDEX(Orçamento!$U:$U,$B23,1)))} | S23: =IF(S$21>$D23,"",IF($G23=$E$6,INDEX(Orçamento!$U:$U,MATCH(S$21,Orçamento!$C:$C,),1),INDEX(Orçamento!$U:$U,MATCH(S$21&"-"&$F24,Orçamento!$F:$F,),1))) | T23: =IF(T$21>$D23,"",IF($G23=$E$6,INDEX(Orçamento!$U:$U,MATCH(T$21,Orçamento!$C:$C,),1),INDEX(Orçamento!$U:$U,MATCH(T$21&"-"&$F24,Orçamento!$F:$F,),1))) | U23: =IF(U$21>$D23,"",IF($G23=$E$6,INDEX(Orçamento!$U:$U,MATCH(U$21,Orçamento!$C:$C,),1),INDEX(Orçamento!$U:$U,MATCH(U$21&"-"&$F24,Orçamento!$F:$F,),1))) | V23: =IF(V$21>$D23,"",IF($G23=$E$6,INDEX(Orçamento!$U:$U,MATCH(V$21,Orçamento!$C:$C,),1),INDEX(Orçamento!$U:$U,MATCH(V$21&"-"&$F24,Orçamento!$F:$F,),1))) | W23: =IF(W$21>$D23,"",IF($G23=$E$6,INDEX(Orçamento!$U:$U,MATCH(W$21,Orçamento!$C:$C,),1),INDEX(Orçamento!$U:$U,MATCH(W$21&"-"&$F24,Orçamento!$F:$F,),1))) | X23: =IF(X$21>$D23,"",IF($G23=$E$6,INDEX(Orçamento!$U:$U,MATCH(X$21,Orçamento!$C:$C,),1),INDEX(Orçamento!$U:$U,MATCH(X$21&"-"&$F24,Orçamento!$F:$F,),1))) | Y23: =IF(Y$21>$D23,"",IF($G23=$E$6,INDEX(Orçamento!$U:$U,MATCH(Y$21,Orçamento!$C:$C,),1),INDEX(Orçamento!$U:$U,MATCH(Y$21&"-"&$F24,Orçamento!$F:$F,),1))) | Z23: =IF(Z$21>$D23,"",IF($G23=$E$6,INDEX(Orçamento!$U:$U,MATCH(Z$21,Orçamento!$C:$C,),1),INDEX(Orçamento!$U:$U,MATCH(Z$21&"-"&$F24,Orçamento!$F:$F,),1))) | ... AK23: =IF(AK$21>$D23,"",IF($G23=$E$6,INDEX(Orçamento!$U:$U,MATCH(AK$21,Orçamento!$C:$C,),1),INDEX(Orçamento!$U:$U,MATCH(AK$21&"-"&$F24,Orçamento!$F:$F,),1)))
B24: =IF($F23>$E$2,0,(1/(1-B25-C25))*(B25+C25)) -> 0 | C24: {=IF(ROUND(SUM(IF(R23:AK23<>"",(R24:AK24)))-N23,3)<>0,"X",0)} -> 0 | E24: {=IF($F23>$E$2,"",INDEX('QC rev00'!$J$9:$J$120,1+E23,1))} | F24: {=IF($F23>$E$2,"",IF($F$2=1,INDEX('QC rev00'!$M$10:$T$120,$F25,1),IF($F$2=2,INDEX(#REF!,$F25,1),INDEX(#REF!,$F25,1))))} | Q24: Qtd | R24: {=IF(OR($D23=0,R23="",$N23=0),"", IF($G23=$E$6, SUM(IF(OFFSET($R$23,,,($F23-1)*3-2,$D$3)=R23,OFFSET($R$25,,,($F23-1)*3-2,$D$3)*OFFSET($B$23,1,,($F23-1)*3-2,1))), IF($D23=1,$N23, SUMIF(OFFSET(Orçamento!$D$1,$B23-1,,$C23,),$F24&"-"&R23,OFFSET(Orçamento!$I$1,$B23-1,,$C23,))*$N23/$E24)))} | S24: {=IF(OR($D23=0,S23="",$N23=0),"", IF($G23=$E$6, SUM(IF(OFFSET($R$23,,,($F23-1)*3-2,$D$3)=S23,OFFSET($R$25,,,($F23-1)*3-2,$D$3)*OFFSET($B$23,1,,($F23-1)*3-2,1))), IF($D23=1,$N23, SUMIF(OFFSET(Orçamento!$D$1,$B23-1,,$C23,),$F24&"-"&S23,OFFSET(Orçamento!$I$1,$B23-1,,$C23,))*$N23/$E24)))} | T24: {=IF(OR($D23=0,T23="",$N23=0),"", IF($G23=$E$6, SUM(IF(OFFSET($R$23,,,($F23-1)*3-2,$D$3)=T23,OFFSET($R$25,,,($F23-1)*3-2,$D$3)*OFFSET($B$23,1,,($F23-1)*3-2,1))), IF($D23=1,$N23, SUMIF(OFFSET(Orçamento!$D$1,$B23-1,,$C23,),$F24&"-"&T23,OFFSET(Orçamento!$I$1,$B23-1,,$C23,))*$N23/$E24)))} | U24: {=IF(OR($D23=0,U23="",$N23=0),"", IF($G23=$E$6, SUM(IF(OFFSET($R$23,,,($F23-1)*3-2,$D$3)=U23,OFFSET($R$25,,,($F23-1)*3-2,$D$3)*OFFSET($B$23,1,,($F23-1)*3-2,1))), IF($D23=1,$N23, SUMIF(OFFSET(Orçamento!$D$1,$B23-1,,$C23,),$F24&"-"&U23,OFFSET(Orçamento!$I$1,$B23-1,,$C23,))*$N23/$E24)))} | V24: {=IF(OR($D23=0,V23="",$N23=0),"", IF($G23=$E$6, SUM(IF(OFFSET($R$23,,,($F23-1)*3-2,$D$3)=V23,OFFSET($R$25,,,($F23-1)*3-2,$D$3)*OFFSET($B$23,1,,($F23-1)*3-2,1))), IF($D23=1,$N23, SUMIF(OFFSET(Orçamento!$D$1,$B23-1,,$C23,),$F24&"-"&V23,OFFSET(Orçamento!$I$1,$B23-1,,$C23,))*$N23/$E24)))} | W24: {=IF(OR($D23=0,W23="",$N23=0),"", IF($G23=$E$6, SUM(IF(OFFSET($R$23,,,($F23-1)*3-2,$D$3)=W23,OFFSET($R$25,,,($F23-1)*3-2,$D$3)*OFFSET($B$23,1,,($F23-1)*3-2,1))), IF($D23=1,$N23, SUMIF(OFFSET(Orçamento!$D$1,$B23-1,,$C23,),$F24&"-"&W23,OFFSET(Orçamento!$I$1,$B23-1,,$C23,))*$N23/$E24)))} | X24: {=IF(OR($D23=0,X23="",$N23=0),"", IF($G23=$E$6, SUM(IF(OFFSET($R$23,,,($F23-1)*3-2,$D$3)=X23,OFFSET($R$25,,,($F23-1)*3-2,$D$3)*OFFSET($B$23,1,,($F23-1)*3-2,1))), IF($D23=1,$N23, SUMIF(OFFSET(Orçamento!$D$1,$B23-1,,$C23,),$F24&"-"&X23,OFFSET(Orçamento!$I$1,$B23-1,,$C23,))*$N23/$E24)))} | Y24: {=IF(OR($D23=0,Y23="",$N23=0),"", IF($G23=$E$6, SUM(IF(OFFSET($R$23,,,($F23-1)*3-2,$D$3)=Y23,OFFSET($R$25,,,($F23-1)*3-2,$D$3)*OFFSET($B$23,1,,($F23-1)*3-2,1))), IF($D23=1,$N23, SUMIF(OFFSET(Orçamento!$D$1,$B23-1,,$C23,),$F24&"-"&Y23,OFFSET(Orçamento!$I$1,$B23-1,,$C23,))*$N23/$E24)))} | ... AK24: {=IF(OR($D23=0,AK23="",$N23=0),"", IF($G23=$E$6, SUM(IF(OFFSET($R$23,,,($F23-1)*3-2,$D$3)=AK23,OFFSET($R$25,,,($F23-1)*3-2,$D$3)*OFFSET($B$23,1,,($F23-1)*3-2,1))), IF($D23=1,$N23, SUMIF(OFFSET(Orçamento!$D$1,$B23-1,,$C23,),$F24&"-"&AK23,OFFSET(Orçamento!$I$1,$B23-1,,$C23,))*$N23/$E24)))}
B25: {=IF($F23>$E$2,"",IF($F$2=1,INDEX('QC rev00'!$M$10:$T$120,$F25,5),IF($F$2=2,INDEX(#REF!,$F25,5),INDEX(#REF!,$F25,5))))} | C25: {=IF($F23>$E$2,"",IF($F$2=1,INDEX('QC rev00'!$M$10:$T$120,$F25,6),IF($F$2=2,INDEX(#REF!,$F25,6),INDEX(#REF!,$F25,6))))} | F25: =IF(F23>$E$2,"",MATCH(F23,'QC rev00'!$C$10:$C$120,)) | Q25: Valor | R25: =IFERROR(R24*$O23,0) -> 0 | S25: =IFERROR(S24*$O23,0) -> 0 | T25: =IFERROR(T24*$O23,0) -> 0 | U25: =IFERROR(U24*$O23,0) -> 0 | V25: =IFERROR(V24*$O23,0) -> 0 | W25: =IFERROR(W24*$O23,0) -> 0 | X25: =IFERROR(X24*$O23,0) -> 0 | Y25: =IFERROR(Y24*$O23,0) -> 0 | ... AK25: =IFERROR(AK24*$O23,0) -> 0
B26: =IF($F26>$E$2,0,IF(E26<>"",MATCH(F27&" - Mapa",Orçamento!J:J,),0)) -> 0 | C26: =IF($D26>1,_xlfn.MAXIFS(Orçamento!G:G,Orçamento!J:J,F27&" - Mapa")+6-B26,0) -> 0 | D26: =IF($F26>$E$2,0,IF($G26=$E$6,$D$2,IF(E26<>"",_xlfn.MAXIFS(Orçamento!E:E,Orçamento!J:J,F27&" - Mapa"),0))) -> 0 | E26: =IF(F27="","",_xlfn.IFNA(MATCH($F27,'QC rev00'!$G$10:$G$120,),"")) | F26: {=OFFSET(F26,-3,,,)+1} -> 2 | G26: {=IF($F26>$E$2,"",IF($F$2=1,INDEX('QC rev00'!$M$10:$T$120,$F28,2),IF($F$2=2,INDEX(#REF!,$F28,2),INDEX(#REF!,$F28,2))))} | H26: {=IF($F26>$E$2,"",IF($F$2=1,INDEX('QC rev00'!$M$10:$T$120,$F28,3),IF($F$2=2,INDEX(#REF!,$F28,3),INDEX(#REF!,$F28,3))))} | L26: {=IF($F26>$E$2,"",IF($F$2=1,INDEX('QC rev00'!$M$10:$T$120,$F28,7),IF($F$2=2,INDEX(#REF!,$F28,7),INDEX(#REF!,$F28,7))))} | M26: {=IF($F26>$E$2,"",IF($F$2=1,INDEX('QC rev00'!$M$10:$T$120,$F28,8),IF($F$2=2,INDEX(#REF!,$F28,8),INDEX(#REF!,$F28,8))))} | N26: {=IF($F26>$E$2,0,IF(_xlfn.IFNA(MATCH($G26,Listas!$E$4:$E$206,),0)>0,$F$5,IF($F$2=1,INDEX('QC rev00'!$M$10:$U$120,$F28,9),IF($F$2=2,INDEX(#REF!,$F28,9),INDEX(#REF!,$F28,9)))))} -> 0 | O26: {=IF($F26>$E$2,0,IF(_xlfn.IFNA(MATCH($G26,Listas!$E$4:$E$206,),0)>0,1,IF($H$10=0,0,IF($F$2=1,INDEX('QC rev00'!$M$10:$BC$120,$F28,9+$F$3),IF($F$2=2,INDEX(#REF!,$F28,9+$F$3),INDEX(#REF!,$F28,9+$F$3)))*IF($E$5="X",1,1-$B28-$C28))))} -> 0 | P26: =N26*O26 -> 0 | Q26: IP | R26: {=IF($D26=0,"",IF($G26=$E$6,INDEX(Orçamento!$U:$U,MATCH(R$21,Orçamento!$C:$C,),1),INDEX(Orçamento!$U:$U,$B26,1)))} | S26: =IF(S$21>$D26,"",IF($G26=$E$6,INDEX(Orçamento!$U:$U,MATCH(S$21,Orçamento!$C:$C,),1),INDEX(Orçamento!$U:$U,MATCH(S$21&"-"&$F27,Orçamento!$F:$F,),1))) | T26: =IF(T$21>$D26,"",IF($G26=$E$6,INDEX(Orçamento!$U:$U,MATCH(T$21,Orçamento!$C:$C,),1),INDEX(Orçamento!$U:$U,MATCH(T$21&"-"&$F27,Orçamento!$F:$F,),1))) | U26: =IF(U$21>$D26,"",IF($G26=$E$6,INDEX(Orçamento!$U:$U,MATCH(U$21,Orçamento!$C:$C,),1),INDEX(Orçamento!$U:$U,MATCH(U$21&"-"&$F27,Orçamento!$F:$F,),1))) | V26: =IF(V$21>$D26,"",IF($G26=$E$6,INDEX(Orçamento!$U:$U,MATCH(V$21,Orçamento!$C:$C,),1),INDEX(Orçamento!$U:$U,MATCH(V$21&"-"&$F27,Orçamento!$F:$F,),1))) | W26: =IF(W$21>$D26,"",IF($G26=$E$6,INDEX(Orçamento!$U:$U,MATCH(W$21,Orçamento!$C:$C,),1),INDEX(Orçamento!$U:$U,MATCH(W$21&"-"&$F27,Orçamento!$F:$F,),1))) | X26: =IF(X$21>$D26,"",IF($G26=$E$6,INDEX(Orçamento!$U:$U,MATCH(X$21,Orçamento!$C:$C,),1),INDEX(Orçamento!$U:$U,MATCH(X$21&"-"&$F27,Orçamento!$F:$F,),1))) | Y26: =IF(Y$21>$D26,"",IF($G26=$E$6,INDEX(Orçamento!$U:$U,MATCH(Y$21,Orçamento!$C:$C,),1),INDEX(Orçamento!$U:$U,MATCH(Y$21&"-"&$F27,Orçamento!$F:$F,),1))) | Z26: =IF(Z$21>$D26,"",IF($G26=$E$6,INDEX(Orçamento!$U:$U,MATCH(Z$21,Orçamento!$C:$C,),1),INDEX(Orçamento!$U:$U,MATCH(Z$21&"-"&$F27,Orçamento!$F:$F,),1))) | ... AK26: =IF(AK$21>$D26,"",IF($G26=$E$6,INDEX(Orçamento!$U:$U,MATCH(AK$21,Orçamento!$C:$C,),1),INDEX(Orçamento!$U:$U,MATCH(AK$21&"-"&$F27,Orçamento!$F:$F,),1)))
B27: =IF($F26>$E$2,0,(1/(1-B28-C28))*(B28+C28)) -> 0 | C27: {=IF(ROUND(SUM(IF(R26:AK26<>"",(R27:AK27)))-N26,3)<>0,"X",0)} -> 0 | E27: {=IF($F26>$E$2,"",INDEX('QC rev00'!$J$9:$J$120,1+E26,1))} | F27: {=IF($F26>$E$2,"",IF($F$2=1,INDEX('QC rev00'!$M$10:$T$120,$F28,1),IF($F$2=2,INDEX(#REF!,$F28,1),INDEX(#REF!,$F28,1))))} | Q27: Qtd | R27: {=IF(OR($D26=0,R26="",$N26=0),"", IF($G26=$E$6, SUM(IF(OFFSET($R$23,,,($F26-1)*3-2,$D$3)=R26,OFFSET($R$25,,,($F26-1)*3-2,$D$3)*OFFSET($B$23,1,,($F26-1)*3-2,1))), IF($D26=1,$N26, SUMIF(OFFSET(Orçamento!$D$1,$B26-1,,$C26,),$F27&"-"&R26,OFFSET(Orçamento!$I$1,$B26-1,,$C26,))*$N26/$E27)))} | S27: {=IF(OR($D26=0,S26="",$N26=0),"", IF($G26=$E$6, SUM(IF(OFFSET($R$23,,,($F26-1)*3-2,$D$3)=S26,OFFSET($R$25,,,($F26-1)*3-2,$D$3)*OFFSET($B$23,1,,($F26-1)*3-2,1))), IF($D26=1,$N26, SUMIF(OFFSET(Orçamento!$D$1,$B26-1,,$C26,),$F27&"-"&S26,OFFSET(Orçamento!$I$1,$B26-1,,$C26,))*$N26/$E27)))} | T27: {=IF(OR($D26=0,T26="",$N26=0),"", IF($G26=$E$6, SUM(IF(OFFSET($R$23,,,($F26-1)*3-2,$D$3)=T26,OFFSET($R$25,,,($F26-1)*3-2,$D$3)*OFFSET($B$23,1,,($F26-1)*3-2,1))), IF($D26=1,$N26, SUMIF(OFFSET(Orçamento!$D$1,$B26-1,,$C26,),$F27&"-"&T26,OFFSET(Orçamento!$I$1,$B26-1,,$C26,))*$N26/$E27)))} | U27: {=IF(OR($D26=0,U26="",$N26=0),"", IF($G26=$E$6, SUM(IF(OFFSET($R$23,,,($F26-1)*3-2,$D$3)=U26,OFFSET($R$25,,,($F26-1)*3-2,$D$3)*OFFSET($B$23,1,,($F26-1)*3-2,1))), IF($D26=1,$N26, SUMIF(OFFSET(Orçamento!$D$1,$B26-1,,$C26,),$F27&"-"&U26,OFFSET(Orçamento!$I$1,$B26-1,,$C26,))*$N26/$E27)))} | V27: {=IF(OR($D26=0,V26="",$N26=0),"", IF($G26=$E$6, SUM(IF(OFFSET($R$23,,,($F26-1)*3-2,$D$3)=V26,OFFSET($R$25,,,($F26-1)*3-2,$D$3)*OFFSET($B$23,1,,($F26-1)*3-2,1))), IF($D26=1,$N26, SUMIF(OFFSET(Orçamento!$D$1,$B26-1,,$C26,),$F27&"-"&V26,OFFSET(Orçamento!$I$1,$B26-1,,$C26,))*$N26/$E27)))} | W27: {=IF(OR($D26=0,W26="",$N26=0),"", IF($G26=$E$6, SUM(IF(OFFSET($R$23,,,($F26-1)*3-2,$D$3)=W26,OFFSET($R$25,,,($F26-1)*3-2,$D$3)*OFFSET($B$23,1,,($F26-1)*3-2,1))), IF($D26=1,$N26, SUMIF(OFFSET(Orçamento!$D$1,$B26-1,,$C26,),$F27&"-"&W26,OFFSET(Orçamento!$I$1,$B26-1,,$C26,))*$N26/$E27)))} | X27: {=IF(OR($D26=0,X26="",$N26=0),"", IF($G26=$E$6, SUM(IF(OFFSET($R$23,,,($F26-1)*3-2,$D$3)=X26,OFFSET($R$25,,,($F26-1)*3-2,$D$3)*OFFSET($B$23,1,,($F26-1)*3-2,1))), IF($D26=1,$N26, SUMIF(OFFSET(Orçamento!$D$1,$B26-1,,$C26,),$F27&"-"&X26,OFFSET(Orçamento!$I$1,$B26-1,,$C26,))*$N26/$E27)))} | Y27: {=IF(OR($D26=0,Y26="",$N26=0),"", IF($G26=$E$6, SUM(IF(OFFSET($R$23,,,($F26-1)*3-2,$D$3)=Y26,OFFSET($R$25,,,($F26-1)*3-2,$D$3)*OFFSET($B$23,1,,($F26-1)*3-2,1))), IF($D26=1,$N26, SUMIF(OFFSET(Orçamento!$D$1,$B26-1,,$C26,),$F27&"-"&Y26,OFFSET(Orçamento!$I$1,$B26-1,,$C26,))*$N26/$E27)))} | ... AK27: {=IF(OR($D26=0,AK26="",$N26=0),"", IF($G26=$E$6, SUM(IF(OFFSET($R$23,,,($F26-1)*3-2,$D$3)=AK26,OFFSET($R$25,,,($F26-1)*3-2,$D$3)*OFFSET($B$23,1,,($F26-1)*3-2,1))), IF($D26=1,$N26, SUMIF(OFFSET(Orçamento!$D$1,$B26-1,,$C26,),$F27&"-"&AK26,OFFSET(Orçamento!$I$1,$B26-1,,$C26,))*$N26/$E27)))}
B28: {=IF($F26>$E$2,"",IF($F$2=1,INDEX('QC rev00'!$M$10:$T$120,$F28,5),IF($F$2=2,INDEX(#REF!,$F28,5),INDEX(#REF!,$F28,5))))} | C28: {=IF($F26>$E$2,"",IF($F$2=1,INDEX('QC rev00'!$M$10:$T$120,$F28,6),IF($F$2=2,INDEX(#REF!,$F28,6),INDEX(#REF!,$F28,6))))} | F28: =IF(F26>$E$2,"",MATCH(F26,'QC rev00'!$C$10:$C$120,)) | Q28: Valor | R28: =IFERROR(R27*$O26,0) -> 0 | S28: =IFERROR(S27*$O26,0) -> 0 | T28: =IFERROR(T27*$O26,0) -> 0 | U28: =IFERROR(U27*$O26,0) -> 0 | V28: =IFERROR(V27*$O26,0) -> 0 | W28: =IFERROR(W27*$O26,0) -> 0 | X28: =IFERROR(X27*$O26,0) -> 0 | Y28: =IFERROR(Y27*$O26,0) -> 0 | ... AK28: =IFERROR(AK27*$O26,0) -> 0
B29: =IF($F29>$E$2,0,IF(E29<>"",MATCH(F30&" - Mapa",Orçamento!J:J,),0)) -> 0 | C29: =IF($D29>1,_xlfn.MAXIFS(Orçamento!G:G,Orçamento!J:J,F30&" - Mapa")+6-B29,0) -> 0 | D29: =IF($F29>$E$2,0,IF($G29=$E$6,$D$2,IF(E29<>"",_xlfn.MAXIFS(Orçamento!E:E,Orçamento!J:J,F30&" - Mapa"),0))) -> 0 | E29: =IF(F30="","",_xlfn.IFNA(MATCH($F30,'QC rev00'!$G$10:$G$120,),"")) | F29: {=OFFSET(F29,-3,,,)+1} -> 3 | G29: {=IF($F29>$E$2,"",IF($F$2=1,INDEX('QC rev00'!$M$10:$T$120,$F31,2),IF($F$2=2,INDEX(#REF!,$F31,2),INDEX(#REF!,$F31,2))))} | H29: {=IF($F29>$E$2,"",IF($F$2=1,INDEX('QC rev00'!$M$10:$T$120,$F31,3),IF($F$2=2,INDEX(#REF!,$F31,3),INDEX(#REF!,$F31,3))))} | L29: {=IF($F29>$E$2,"",IF($F$2=1,INDEX('QC rev00'!$M$10:$T$120,$F31,7),IF($F$2=2,INDEX(#REF!,$F31,7),INDEX(#REF!,$F31,7))))} | M29: {=IF($F29>$E$2,"",IF($F$2=1,INDEX('QC rev00'!$M$10:$T$120,$F31,8),IF($F$2=2,INDEX(#REF!,$F31,8),INDEX(#REF!,$F31,8))))} | N29: {=IF($F29>$E$2,0,IF(_xlfn.IFNA(MATCH($G29,Listas!$E$4:$E$206,),0)>0,$F$5,IF($F$2=1,INDEX('QC rev00'!$M$10:$U$120,$F31,9),IF($F$2=2,INDEX(#REF!,$F31,9),INDEX(#REF!,$F31,9)))))} -> 0 | O29: {=IF($F29>$E$2,0,IF(_xlfn.IFNA(MATCH($G29,Listas!$E$4:$E$206,),0)>0,1,IF($H$10=0,0,IF($F$2=1,INDEX('QC rev00'!$M$10:$BC$120,$F31,9+$F$3),IF($F$2=2,INDEX(#REF!,$F31,9+$F$3),INDEX(#REF!,$F31,9+$F$3)))*IF($E$5="X",1,1-$B31-$C31))))} -> 0 | P29: =N29*O29 -> 0 | Q29: IP | R29: {=IF($D29=0,"",IF($G29=$E$6,INDEX(Orçamento!$U:$U,MATCH(R$21,Orçamento!$C:$C,),1),INDEX(Orçamento!$U:$U,$B29,1)))} | S29: =IF(S$21>$D29,"",IF($G29=$E$6,INDEX(Orçamento!$U:$U,MATCH(S$21,Orçamento!$C:$C,),1),INDEX(Orçamento!$U:$U,MATCH(S$21&"-"&$F30,Orçamento!$F:$F,),1))) | T29: =IF(T$21>$D29,"",IF($G29=$E$6,INDEX(Orçamento!$U:$U,MATCH(T$21,Orçamento!$C:$C,),1),INDEX(Orçamento!$U:$U,MATCH(T$21&"-"&$F30,Orçamento!$F:$F,),1))) | U29: =IF(U$21>$D29,"",IF($G29=$E$6,INDEX(Orçamento!$U:$U,MATCH(U$21,Orçamento!$C:$C,),1),INDEX(Orçamento!$U:$U,MATCH(U$21&"-"&$F30,Orçamento!$F:$F,),1))) | V29: =IF(V$21>$D29,"",IF($G29=$E$6,INDEX(Orçamento!$U:$U,MATCH(V$21,Orçamento!$C:$C,),1),INDEX(Orçamento!$U:$U,MATCH(V$21&"-"&$F30,Orçamento!$F:$F,),1))) | W29: =IF(W$21>$D29,"",IF($G29=$E$6,INDEX(Orçamento!$U:$U,MATCH(W$21,Orçamento!$C:$C,),1),INDEX(Orçamento!$U:$U,MATCH(W$21&"-"&$F30,Orçamento!$F:$F,),1))) | X29: =IF(X$21>$D29,"",IF($G29=$E$6,INDEX(Orçamento!$U:$U,MATCH(X$21,Orçamento!$C:$C,),1),INDEX(Orçamento!$U:$U,MATCH(X$21&"-"&$F30,Orçamento!$F:$F,),1))) | Y29: =IF(Y$21>$D29,"",IF($G29=$E$6,INDEX(Orçamento!$U:$U,MATCH(Y$21,Orçamento!$C:$C,),1),INDEX(Orçamento!$U:$U,MATCH(Y$21&"-"&$F30,Orçamento!$F:$F,),1))) | Z29: =IF(Z$21>$D29,"",IF($G29=$E$6,INDEX(Orçamento!$U:$U,MATCH(Z$21,Orçamento!$C:$C,),1),INDEX(Orçamento!$U:$U,MATCH(Z$21&"-"&$F30,Orçamento!$F:$F,),1))) | ... AK29: =IF(AK$21>$D29,"",IF($G29=$E$6,INDEX(Orçamento!$U:$U,MATCH(AK$21,Orçamento!$C:$C,),1),INDEX(Orçamento!$U:$U,MATCH(AK$21&"-"&$F30,Orçamento!$F:$F,),1)))
B30: =IF($F29>$E$2,0,(1/(1-B31-C31))*(B31+C31)) -> 0 | C30: {=IF(ROUND(SUM(IF(R29:AK29<>"",(R30:AK30)))-N29,3)<>0,"X",0)} -> 0 | E30: {=IF($F29>$E$2,"",INDEX('QC rev00'!$J$9:$J$120,1+E29,1))} | F30: {=IF($F29>$E$2,"",IF($F$2=1,INDEX('QC rev00'!$M$10:$T$120,$F31,1),IF($F$2=2,INDEX(#REF!,$F31,1),INDEX(#REF!,$F31,1))))} | Q30: Qtd | R30: {=IF(OR($D29=0,R29="",$N29=0),"", IF($G29=$E$6, SUM(IF(OFFSET($R$23,,,($F29-1)*3-2,$D$3)=R29,OFFSET($R$25,,,($F29-1)*3-2,$D$3)*OFFSET($B$23,1,,($F29-1)*3-2,1))), IF($D29=1,$N29, SUMIF(OFFSET(Orçamento!$D$1,$B29-1,,$C29,),$F30&"-"&R29,OFFSET(Orçamento!$I$1,$B29-1,,$C29,))*$N29/$E30)))} | S30: {=IF(OR($D29=0,S29="",$N29=0),"", IF($G29=$E$6, SUM(IF(OFFSET($R$23,,,($F29-1)*3-2,$D$3)=S29,OFFSET($R$25,,,($F29-1)*3-2,$D$3)*OFFSET($B$23,1,,($F29-1)*3-2,1))), IF($D29=1,$N29, SUMIF(OFFSET(Orçamento!$D$1,$B29-1,,$C29,),$F30&"-"&S29,OFFSET(Orçamento!$I$1,$B29-1,,$C29,))*$N29/$E30)))} | T30: {=IF(OR($D29=0,T29="",$N29=0),"", IF($G29=$E$6, SUM(IF(OFFSET($R$23,,,($F29-1)*3-2,$D$3)=T29,OFFSET($R$25,,,($F29-1)*3-2,$D$3)*OFFSET($B$23,1,,($F29-1)*3-2,1))), IF($D29=1,$N29, SUMIF(OFFSET(Orçamento!$D$1,$B29-1,,$C29,),$F30&"-"&T29,OFFSET(Orçamento!$I$1,$B29-1,,$C29,))*$N29/$E30)))} | U30: {=IF(OR($D29=0,U29="",$N29=0),"", IF($G29=$E$6, SUM(IF(OFFSET($R$23,,,($F29-1)*3-2,$D$3)=U29,OFFSET($R$25,,,($F29-1)*3-2,$D$3)*OFFSET($B$23,1,,($F29-1)*3-2,1))), IF($D29=1,$N29, SUMIF(OFFSET(Orçamento!$D$1,$B29-1,,$C29,),$F30&"-"&U29,OFFSET(Orçamento!$I$1,$B29-1,,$C29,))*$N29/$E30)))} | V30: {=IF(OR($D29=0,V29="",$N29=0),"", IF($G29=$E$6, SUM(IF(OFFSET($R$23,,,($F29-1)*3-2,$D$3)=V29,OFFSET($R$25,,,($F29-1)*3-2,$D$3)*OFFSET($B$23,1,,($F29-1)*3-2,1))), IF($D29=1,$N29, SUMIF(OFFSET(Orçamento!$D$1,$B29-1,,$C29,),$F30&"-"&V29,OFFSET(Orçamento!$I$1,$B29-1,,$C29,))*$N29/$E30)))} | W30: {=IF(OR($D29=0,W29="",$N29=0),"", IF($G29=$E$6, SUM(IF(OFFSET($R$23,,,($F29-1)*3-2,$D$3)=W29,OFFSET($R$25,,,($F29-1)*3-2,$D$3)*OFFSET($B$23,1,,($F29-1)*3-2,1))), IF($D29=1,$N29, SUMIF(OFFSET(Orçamento!$D$1,$B29-1,,$C29,),$F30&"-"&W29,OFFSET(Orçamento!$I$1,$B29-1,,$C29,))*$N29/$E30)))} | X30: {=IF(OR($D29=0,X29="",$N29=0),"", IF($G29=$E$6, SUM(IF(OFFSET($R$23,,,($F29-1)*3-2,$D$3)=X29,OFFSET($R$25,,,($F29-1)*3-2,$D$3)*OFFSET($B$23,1,,($F29-1)*3-2,1))), IF($D29=1,$N29, SUMIF(OFFSET(Orçamento!$D$1,$B29-1,,$C29,),$F30&"-"&X29,OFFSET(Orçamento!$I$1,$B29-1,,$C29,))*$N29/$E30)))} | Y30: {=IF(OR($D29=0,Y29="",$N29=0),"", IF($G29=$E$6, SUM(IF(OFFSET($R$23,,,($F29-1)*3-2,$D$3)=Y29,OFFSET($R$25,,,($F29-1)*3-2,$D$3)*OFFSET($B$23,1,,($F29-1)*3-2,1))), IF($D29=1,$N29, SUMIF(OFFSET(Orçamento!$D$1,$B29-1,,$C29,),$F30&"-"&Y29,OFFSET(Orçamento!$I$1,$B29-1,,$C29,))*$N29/$E30)))} | ... AK30: {=IF(OR($D29=0,AK29="",$N29=0),"", IF($G29=$E$6, SUM(IF(OFFSET($R$23,,,($F29-1)*3-2,$D$3)=AK29,OFFSET($R$25,,,($F29-1)*3-2,$D$3)*OFFSET($B$23,1,,($F29-1)*3-2,1))), IF($D29=1,$N29, SUMIF(OFFSET(Orçamento!$D$1,$B29-1,,$C29,),$F30&"-"&AK29,OFFSET(Orçamento!$I$1,$B29-1,,$C29,))*$N29/$E30)))}
B31: {=IF($F29>$E$2,"",IF($F$2=1,INDEX('QC rev00'!$M$10:$T$120,$F31,5),IF($F$2=2,INDEX(#REF!,$F31,5),INDEX(#REF!,$F31,5))))} | C31: {=IF($F29>$E$2,"",IF($F$2=1,INDEX('QC rev00'!$M$10:$T$120,$F31,6),IF($F$2=2,INDEX(#REF!,$F31,6),INDEX(#REF!,$F31,6))))} | F31: =IF(F29>$E$2,"",MATCH(F29,'QC rev00'!$C$10:$C$120,)) | Q31: Valor | R31: =IFERROR(R30*$O29,0) -> 0 | S31: =IFERROR(S30*$O29,0) -> 0 | T31: =IFERROR(T30*$O29,0) -> 0 | U31: =IFERROR(U30*$O29,0) -> 0 | V31: =IFERROR(V30*$O29,0) -> 0 | W31: =IFERROR(W30*$O29,0) -> 0 | X31: =IFERROR(X30*$O29,0) -> 0 | Y31: =IFERROR(Y30*$O29,0) -> 0 | ... AK31: =IFERROR(AK30*$O29,0) -> 0
B32: =IF($F32>$E$2,0,IF(E32<>"",MATCH(F33&" - Mapa",Orçamento!J:J,),0)) -> 0 | C32: =IF($D32>1,_xlfn.MAXIFS(Orçamento!G:G,Orçamento!J:J,F33&" - Mapa")+6-B32,0) -> 0 | D32: =IF($F32>$E$2,0,IF($G32=$E$6,$D$2,IF(E32<>"",_xlfn.MAXIFS(Orçamento!E:E,Orçamento!J:J,F33&" - Mapa"),0))) -> 0 | E32: =IF(F33="","",_xlfn.IFNA(MATCH($F33,'QC rev00'!$G$10:$G$120,),"")) | F32: {=OFFSET(F32,-3,,,)+1} -> 4 | G32: {=IF($F32>$E$2,"",IF($F$2=1,INDEX('QC rev00'!$M$10:$T$120,$F34,2),IF($F$2=2,INDEX(#REF!,$F34,2),INDEX(#REF!,$F34,2))))} | H32: {=IF($F32>$E$2,"",IF($F$2=1,INDEX('QC rev00'!$M$10:$T$120,$F34,3),IF($F$2=2,INDEX(#REF!,$F34,3),INDEX(#REF!,$F34,3))))} | L32: {=IF($F32>$E$2,"",IF($F$2=1,INDEX('QC rev00'!$M$10:$T$120,$F34,7),IF($F$2=2,INDEX(#REF!,$F34,7),INDEX(#REF!,$F34,7))))} | M32: {=IF($F32>$E$2,"",IF($F$2=1,INDEX('QC rev00'!$M$10:$T$120,$F34,8),IF($F$2=2,INDEX(#REF!,$F34,8),INDEX(#REF!,$F34,8))))} | N32: {=IF($F32>$E$2,0,IF(_xlfn.IFNA(MATCH($G32,Listas!$E$4:$E$206,),0)>0,$F$5,IF($F$2=1,INDEX('QC rev00'!$M$10:$U$120,$F34,9),IF($F$2=2,INDEX(#REF!,$F34,9),INDEX(#REF!,$F34,9)))))} -> 0 | O32: {=IF($F32>$E$2,0,IF(_xlfn.IFNA(MATCH($G32,Listas!$E$4:$E$206,),0)>0,1,IF($H$10=0,0,IF($F$2=1,INDEX('QC rev00'!$M$10:$BC$120,$F34,9+$F$3),IF($F$2=2,INDEX(#REF!,$F34,9+$F$3),INDEX(#REF!,$F34,9+$F$3)))*IF($E$5="X",1,1-$B34-$C34))))} -> 0 | P32: =N32*O32 -> 0 | Q32: IP | R32: {=IF($D32=0,"",IF($G32=$E$6,INDEX(Orçamento!$U:$U,MATCH(R$21,Orçamento!$C:$C,),1),INDEX(Orçamento!$U:$U,$B32,1)))} | S32: =IF(S$21>$D32,"",IF($G32=$E$6,INDEX(Orçamento!$U:$U,MATCH(S$21,Orçamento!$C:$C,),1),INDEX(Orçamento!$U:$U,MATCH(S$21&"-"&$F33,Orçamento!$F:$F,),1))) | T32: =IF(T$21>$D32,"",IF($G32=$E$6,INDEX(Orçamento!$U:$U,MATCH(T$21,Orçamento!$C:$C,),1),INDEX(Orçamento!$U:$U,MATCH(T$21&"-"&$F33,Orçamento!$F:$F,),1))) | U32: =IF(U$21>$D32,"",IF($G32=$E$6,INDEX(Orçamento!$U:$U,MATCH(U$21,Orçamento!$C:$C,),1),INDEX(Orçamento!$U:$U,MATCH(U$21&"-"&$F33,Orçamento!$F:$F,),1))) | V32: =IF(V$21>$D32,"",IF($G32=$E$6,INDEX(Orçamento!$U:$U,MATCH(V$21,Orçamento!$C:$C,),1),INDEX(Orçamento!$U:$U,MATCH(V$21&"-"&$F33,Orçamento!$F:$F,),1))) | W32: =IF(W$21>$D32,"",IF($G32=$E$6,INDEX(Orçamento!$U:$U,MATCH(W$21,Orçamento!$C:$C,),1),INDEX(Orçamento!$U:$U,MATCH(W$21&"-"&$F33,Orçamento!$F:$F,),1))) | X32: =IF(X$21>$D32,"",IF($G32=$E$6,INDEX(Orçamento!$U:$U,MATCH(X$21,Orçamento!$C:$C,),1),INDEX(Orçamento!$U:$U,MATCH(X$21&"-"&$F33,Orçamento!$F:$F,),1))) | Y32: =IF(Y$21>$D32,"",IF($G32=$E$6,INDEX(Orçamento!$U:$U,MATCH(Y$21,Orçamento!$C:$C,),1),INDEX(Orçamento!$U:$U,MATCH(Y$21&"-"&$F33,Orçamento!$F:$F,),1))) | Z32: =IF(Z$21>$D32,"",IF($G32=$E$6,INDEX(Orçamento!$U:$U,MATCH(Z$21,Orçamento!$C:$C,),1),INDEX(Orçamento!$U:$U,MATCH(Z$21&"-"&$F33,Orçamento!$F:$F,),1))) | ... AK32: =IF(AK$21>$D32,"",IF($G32=$E$6,INDEX(Orçamento!$U:$U,MATCH(AK$21,Orçamento!$C:$C,),1),INDEX(Orçamento!$U:$U,MATCH(AK$21&"-"&$F33,Orçamento!$F:$F,),1)))
B33: =IF($F32>$E$2,0,(1/(1-B34-C34))*(B34+C34)) -> 0 | C33: {=IF(ROUND(SUM(IF(R32:AK32<>"",(R33:AK33)))-N32,3)<>0,"X",0)} -> 0 | E33: {=IF($F32>$E$2,"",INDEX('QC rev00'!$J$9:$J$120,1+E32,1))} | F33: {=IF($F32>$E$2,"",IF($F$2=1,INDEX('QC rev00'!$M$10:$T$120,$F34,1),IF($F$2=2,INDEX(#REF!,$F34,1),INDEX(#REF!,$F34,1))))} | Q33: Qtd | R33: {=IF(OR($D32=0,R32="",$N32=0),"", IF($G32=$E$6, SUM(IF(OFFSET($R$23,,,($F32-1)*3-2,$D$3)=R32,OFFSET($R$25,,,($F32-1)*3-2,$D$3)*OFFSET($B$23,1,,($F32-1)*3-2,1))), IF($D32=1,$N32, SUMIF(OFFSET(Orçamento!$D$1,$B32-1,,$C32,),$F33&"-"&R32,OFFSET(Orçamento!$I$1,$B32-1,,$C32,))*$N32/$E33)))} | S33: {=IF(OR($D32=0,S32="",$N32=0),"", IF($G32=$E$6, SUM(IF(OFFSET($R$23,,,($F32-1)*3-2,$D$3)=S32,OFFSET($R$25,,,($F32-1)*3-2,$D$3)*OFFSET($B$23,1,,($F32-1)*3-2,1))), IF($D32=1,$N32, SUMIF(OFFSET(Orçamento!$D$1,$B32-1,,$C32,),$F33&"-"&S32,OFFSET(Orçamento!$I$1,$B32-1,,$C32,))*$N32/$E33)))} | T33: {=IF(OR($D32=0,T32="",$N32=0),"", IF($G32=$E$6, SUM(IF(OFFSET($R$23,,,($F32-1)*3-2,$D$3)=T32,OFFSET($R$25,,,($F32-1)*3-2,$D$3)*OFFSET($B$23,1,,($F32-1)*3-2,1))), IF($D32=1,$N32, SUMIF(OFFSET(Orçamento!$D$1,$B32-1,,$C32,),$F33&"-"&T32,OFFSET(Orçamento!$I$1,$B32-1,,$C32,))*$N32/$E33)))} | U33: {=IF(OR($D32=0,U32="",$N32=0),"", IF($G32=$E$6, SUM(IF(OFFSET($R$23,,,($F32-1)*3-2,$D$3)=U32,OFFSET($R$25,,,($F32-1)*3-2,$D$3)*OFFSET($B$23,1,,($F32-1)*3-2,1))), IF($D32=1,$N32, SUMIF(OFFSET(Orçamento!$D$1,$B32-1,,$C32,),$F33&"-"&U32,OFFSET(Orçamento!$I$1,$B32-1,,$C32,))*$N32/$E33)))} | V33: {=IF(OR($D32=0,V32="",$N32=0),"", IF($G32=$E$6, SUM(IF(OFFSET($R$23,,,($F32-1)*3-2,$D$3)=V32,OFFSET($R$25,,,($F32-1)*3-2,$D$3)*OFFSET($B$23,1,,($F32-1)*3-2,1))), IF($D32=1,$N32, SUMIF(OFFSET(Orçamento!$D$1,$B32-1,,$C32,),$F33&"-"&V32,OFFSET(Orçamento!$I$1,$B32-1,,$C32,))*$N32/$E33)))} | W33: {=IF(OR($D32=0,W32="",$N32=0),"", IF($G32=$E$6, SUM(IF(OFFSET($R$23,,,($F32-1)*3-2,$D$3)=W32,OFFSET($R$25,,,($F32-1)*3-2,$D$3)*OFFSET($B$23,1,,($F32-1)*3-2,1))), IF($D32=1,$N32, SUMIF(OFFSET(Orçamento!$D$1,$B32-1,,$C32,),$F33&"-"&W32,OFFSET(Orçamento!$I$1,$B32-1,,$C32,))*$N32/$E33)))} | X33: {=IF(OR($D32=0,X32="",$N32=0),"", IF($G32=$E$6, SUM(IF(OFFSET($R$23,,,($F32-1)*3-2,$D$3)=X32,OFFSET($R$25,,,($F32-1)*3-2,$D$3)*OFFSET($B$23,1,,($F32-1)*3-2,1))), IF($D32=1,$N32, SUMIF(OFFSET(Orçamento!$D$1,$B32-1,,$C32,),$F33&"-"&X32,OFFSET(Orçamento!$I$1,$B32-1,,$C32,))*$N32/$E33)))} | Y33: {=IF(OR($D32=0,Y32="",$N32=0),"", IF($G32=$E$6, SUM(IF(OFFSET($R$23,,,($F32-1)*3-2,$D$3)=Y32,OFFSET($R$25,,,($F32-1)*3-2,$D$3)*OFFSET($B$23,1,,($F32-1)*3-2,1))), IF($D32=1,$N32, SUMIF(OFFSET(Orçamento!$D$1,$B32-1,,$C32,),$F33&"-"&Y32,OFFSET(Orçamento!$I$1,$B32-1,,$C32,))*$N32/$E33)))} | ... AK33: {=IF(OR($D32=0,AK32="",$N32=0),"", IF($G32=$E$6, SUM(IF(OFFSET($R$23,,,($F32-1)*3-2,$D$3)=AK32,OFFSET($R$25,,,($F32-1)*3-2,$D$3)*OFFSET($B$23,1,,($F32-1)*3-2,1))), IF($D32=1,$N32, SUMIF(OFFSET(Orçamento!$D$1,$B32-1,,$C32,),$F33&"-"&AK32,OFFSET(Orçamento!$I$1,$B32-1,,$C32,))*$N32/$E33)))}
B34: {=IF($F32>$E$2,"",IF($F$2=1,INDEX('QC rev00'!$M$10:$T$120,$F34,5),IF($F$2=2,INDEX(#REF!,$F34,5),INDEX(#REF!,$F34,5))))} | C34: {=IF($F32>$E$2,"",IF($F$2=1,INDEX('QC rev00'!$M$10:$T$120,$F34,6),IF($F$2=2,INDEX(#REF!,$F34,6),INDEX(#REF!,$F34,6))))} | F34: =IF(F32>$E$2,"",MATCH(F32,'QC rev00'!$C$10:$C$120,)) | Q34: Valor | R34: =IFERROR(R33*$O32,0) -> 0 | S34: =IFERROR(S33*$O32,0) -> 0 | T34: =IFERROR(T33*$O32,0) -> 0 | U34: =IFERROR(U33*$O32,0) -> 0 | V34: =IFERROR(V33*$O32,0) -> 0 | W34: =IFERROR(W33*$O32,0) -> 0 | X34: =IFERROR(X33*$O32,0) -> 0 | Y34: =IFERROR(Y33*$O32,0) -> 0 | ... AK34: =IFERROR(AK33*$O32,0) -> 0
B35: =IF($F35>$E$2,0,IF(E35<>"",MATCH(F36&" - Mapa",Orçamento!J:J,),0)) -> 0 | C35: =IF($D35>1,_xlfn.MAXIFS(Orçamento!G:G,Orçamento!J:J,F36&" - Mapa")+6-B35,0) -> 0 | D35: =IF($F35>$E$2,0,IF($G35=$E$6,$D$2,IF(E35<>"",_xlfn.MAXIFS(Orçamento!E:E,Orçamento!J:J,F36&" - Mapa"),0))) -> 0 | E35: =IF(F36="","",_xlfn.IFNA(MATCH($F36,'QC rev00'!$G$10:$G$120,),"")) | F35: {=OFFSET(F35,-3,,,)+1} -> 5 | G35: {=IF($F35>$E$2,"",IF($F$2=1,INDEX('QC rev00'!$M$10:$T$120,$F37,2),IF($F$2=2,INDEX(#REF!,$F37,2),INDEX(#REF!,$F37,2))))} | H35: {=IF($F35>$E$2,"",IF($F$2=1,INDEX('QC rev00'!$M$10:$T$120,$F37,3),IF($F$2=2,INDEX(#REF!,$F37,3),INDEX(#REF!,$F37,3))))} | L35: {=IF($F35>$E$2,"",IF($F$2=1,INDEX('QC rev00'!$M$10:$T$120,$F37,7),IF($F$2=2,INDEX(#REF!,$F37,7),INDEX(#REF!,$F37,7))))} | M35: {=IF($F35>$E$2,"",IF($F$2=1,INDEX('QC rev00'!$M$10:$T$120,$F37,8),IF($F$2=2,INDEX(#REF!,$F37,8),INDEX(#REF!,$F37,8))))} | N35: {=IF($F35>$E$2,0,IF(_xlfn.IFNA(MATCH($G35,Listas!$E$4:$E$206,),0)>0,$F$5,IF($F$2=1,INDEX('QC rev00'!$M$10:$U$120,$F37,9),IF($F$2=2,INDEX(#REF!,$F37,9),INDEX(#REF!,$F37,9)))))} -> 0 | O35: {=IF($F35>$E$2,0,IF(_xlfn.IFNA(MATCH($G35,Listas!$E$4:$E$206,),0)>0,1,IF($H$10=0,0,IF($F$2=1,INDEX('QC rev00'!$M$10:$BC$120,$F37,9+$F$3),IF($F$2=2,INDEX(#REF!,$F37,9+$F$3),INDEX(#REF!,$F37,9+$F$3)))*IF($E$5="X",1,1-$B37-$C37))))} -> 0 | P35: =N35*O35 -> 0 | Q35: IP | R35: {=IF($D35=0,"",IF($G35=$E$6,INDEX(Orçamento!$U:$U,MATCH(R$21,Orçamento!$C:$C,),1),INDEX(Orçamento!$U:$U,$B35,1)))} | S35: =IF(S$21>$D35,"",IF($G35=$E$6,INDEX(Orçamento!$U:$U,MATCH(S$21,Orçamento!$C:$C,),1),INDEX(Orçamento!$U:$U,MATCH(S$21&"-"&$F36,Orçamento!$F:$F,),1))) | T35: =IF(T$21>$D35,"",IF($G35=$E$6,INDEX(Orçamento!$U:$U,MATCH(T$21,Orçamento!$C:$C,),1),INDEX(Orçamento!$U:$U,MATCH(T$21&"-"&$F36,Orçamento!$F:$F,),1))) | U35: =IF(U$21>$D35,"",IF($G35=$E$6,INDEX(Orçamento!$U:$U,MATCH(U$21,Orçamento!$C:$C,),1),INDEX(Orçamento!$U:$U,MATCH(U$21&"-"&$F36,Orçamento!$F:$F,),1))) | V35: =IF(V$21>$D35,"",IF($G35=$E$6,INDEX(Orçamento!$U:$U,MATCH(V$21,Orçamento!$C:$C,),1),INDEX(Orçamento!$U:$U,MATCH(V$21&"-"&$F36,Orçamento!$F:$F,),1))) | W35: =IF(W$21>$D35,"",IF($G35=$E$6,INDEX(Orçamento!$U:$U,MATCH(W$21,Orçamento!$C:$C,),1),INDEX(Orçamento!$U:$U,MATCH(W$21&"-"&$F36,Orçamento!$F:$F,),1))) | X35: =IF(X$21>$D35,"",IF($G35=$E$6,INDEX(Orçamento!$U:$U,MATCH(X$21,Orçamento!$C:$C,),1),INDEX(Orçamento!$U:$U,MATCH(X$21&"-"&$F36,Orçamento!$F:$F,),1))) | Y35: =IF(Y$21>$D35,"",IF($G35=$E$6,INDEX(Orçamento!$U:$U,MATCH(Y$21,Orçamento!$C:$C,),1),INDEX(Orçamento!$U:$U,MATCH(Y$21&"-"&$F36,Orçamento!$F:$F,),1))) | Z35: =IF(Z$21>$D35,"",IF($G35=$E$6,INDEX(Orçamento!$U:$U,MATCH(Z$21,Orçamento!$C:$C,),1),INDEX(Orçamento!$U:$U,MATCH(Z$21&"-"&$F36,Orçamento!$F:$F,),1))) | ... AK35: =IF(AK$21>$D35,"",IF($G35=$E$6,INDEX(Orçamento!$U:$U,MATCH(AK$21,Orçamento!$C:$C,),1),INDEX(Orçamento!$U:$U,MATCH(AK$21&"-"&$F36,Orçamento!$F:$F,),1)))
B36: =IF($F35>$E$2,0,(1/(1-B37-C37))*(B37+C37)) -> 0 | C36: {=IF(ROUND(SUM(IF(R35:AK35<>"",(R36:AK36)))-N35,3)<>0,"X",0)} -> 0 | E36: {=IF($F35>$E$2,"",INDEX('QC rev00'!$J$9:$J$120,1+E35,1))} | F36: {=IF($F35>$E$2,"",IF($F$2=1,INDEX('QC rev00'!$M$10:$T$120,$F37,1),IF($F$2=2,INDEX(#REF!,$F37,1),INDEX(#REF!,$F37,1))))} | Q36: Qtd | R36: {=IF(OR($D35=0,R35="",$N35=0),"", IF($G35=$E$6, SUM(IF(OFFSET($R$23,,,($F35-1)*3-2,$D$3)=R35,OFFSET($R$25,,,($F35-1)*3-2,$D$3)*OFFSET($B$23,1,,($F35-1)*3-2,1))), IF($D35=1,$N35, SUMIF(OFFSET(Orçamento!$D$1,$B35-1,,$C35,),$F36&"-"&R35,OFFSET(Orçamento!$I$1,$B35-1,,$C35,))*$N35/$E36)))} | S36: {=IF(OR($D35=0,S35="",$N35=0),"", IF($G35=$E$6, SUM(IF(OFFSET($R$23,,,($F35-1)*3-2,$D$3)=S35,OFFSET($R$25,,,($F35-1)*3-2,$D$3)*OFFSET($B$23,1,,($F35-1)*3-2,1))), IF($D35=1,$N35, SUMIF(OFFSET(Orçamento!$D$1,$B35-1,,$C35,),$F36&"-"&S35,OFFSET(Orçamento!$I$1,$B35-1,,$C35,))*$N35/$E36)))} | T36: {=IF(OR($D35=0,T35="",$N35=0),"", IF($G35=$E$6, SUM(IF(OFFSET($R$23,,,($F35-1)*3-2,$D$3)=T35,OFFSET($R$25,,,($F35-1)*3-2,$D$3)*OFFSET($B$23,1,,($F35-1)*3-2,1))), IF($D35=1,$N35, SUMIF(OFFSET(Orçamento!$D$1,$B35-1,,$C35,),$F36&"-"&T35,OFFSET(Orçamento!$I$1,$B35-1,,$C35,))*$N35/$E36)))} | U36: {=IF(OR($D35=0,U35="",$N35=0),"", IF($G35=$E$6, SUM(IF(OFFSET($R$23,,,($F35-1)*3-2,$D$3)=U35,OFFSET($R$25,,,($F35-1)*3-2,$D$3)*OFFSET($B$23,1,,($F35-1)*3-2,1))), IF($D35=1,$N35, SUMIF(OFFSET(Orçamento!$D$1,$B35-1,,$C35,),$F36&"-"&U35,OFFSET(Orçamento!$I$1,$B35-1,,$C35,))*$N35/$E36)))} | V36: {=IF(OR($D35=0,V35="",$N35=0),"", IF($G35=$E$6, SUM(IF(OFFSET($R$23,,,($F35-1)*3-2,$D$3)=V35,OFFSET($R$25,,,($F35-1)*3-2,$D$3)*OFFSET($B$23,1,,($F35-1)*3-2,1))), IF($D35=1,$N35, SUMIF(OFFSET(Orçamento!$D$1,$B35-1,,$C35,),$F36&"-"&V35,OFFSET(Orçamento!$I$1,$B35-1,,$C35,))*$N35/$E36)))} | W36: {=IF(OR($D35=0,W35="",$N35=0),"", IF($G35=$E$6, SUM(IF(OFFSET($R$23,,,($F35-1)*3-2,$D$3)=W35,OFFSET($R$25,,,($F35-1)*3-2,$D$3)*OFFSET($B$23,1,,($F35-1)*3-2,1))), IF($D35=1,$N35, SUMIF(OFFSET(Orçamento!$D$1,$B35-1,,$C35,),$F36&"-"&W35,OFFSET(Orçamento!$I$1,$B35-1,,$C35,))*$N35/$E36)))} | X36: {=IF(OR($D35=0,X35="",$N35=0),"", IF($G35=$E$6, SUM(IF(OFFSET($R$23,,,($F35-1)*3-2,$D$3)=X35,OFFSET($R$25,,,($F35-1)*3-2,$D$3)*OFFSET($B$23,1,,($F35-1)*3-2,1))), IF($D35=1,$N35, SUMIF(OFFSET(Orçamento!$D$1,$B35-1,,$C35,),$F36&"-"&X35,OFFSET(Orçamento!$I$1,$B35-1,,$C35,))*$N35/$E36)))} | Y36: {=IF(OR($D35=0,Y35="",$N35=0),"", IF($G35=$E$6, SUM(IF(OFFSET($R$23,,,($F35-1)*3-2,$D$3)=Y35,OFFSET($R$25,,,($F35-1)*3-2,$D$3)*OFFSET($B$23,1,,($F35-1)*3-2,1))), IF($D35=1,$N35, SUMIF(OFFSET(Orçamento!$D$1,$B35-1,,$C35,),$F36&"-"&Y35,OFFSET(Orçamento!$I$1,$B35-1,,$C35,))*$N35/$E36)))} | ... AK36: {=IF(OR($D35=0,AK35="",$N35=0),"", IF($G35=$E$6, SUM(IF(OFFSET($R$23,,,($F35-1)*3-2,$D$3)=AK35,OFFSET($R$25,,,($F35-1)*3-2,$D$3)*OFFSET($B$23,1,,($F35-1)*3-2,1))), IF($D35=1,$N35, SUMIF(OFFSET(Orçamento!$D$1,$B35-1,,$C35,),$F36&"-"&AK35,OFFSET(Orçamento!$I$1,$B35-1,,$C35,))*$N35/$E36)))}
B37: {=IF($F35>$E$2,"",IF($F$2=1,INDEX('QC rev00'!$M$10:$T$120,$F37,5),IF($F$2=2,INDEX(#REF!,$F37,5),INDEX(#REF!,$F37,5))))} | C37: {=IF($F35>$E$2,"",IF($F$2=1,INDEX('QC rev00'!$M$10:$T$120,$F37,6),IF($F$2=2,INDEX(#REF!,$F37,6),INDEX(#REF!,$F37,6))))} | F37: =IF(F35>$E$2,"",MATCH(F35,'QC rev00'!$C$10:$C$120,)) | Q37: Valor | R37: =IFERROR(R36*$O35,0) -> 0 | S37: =IFERROR(S36*$O35,0) -> 0 | T37: =IFERROR(T36*$O35,0) -> 0 | U37: =IFERROR(U36*$O35,0) -> 0 | V37: =IFERROR(V36*$O35,0) -> 0 | W37: =IFERROR(W36*$O35,0) -> 0 | X37: =IFERROR(X36*$O35,0) -> 0 | Y37: =IFERROR(Y36*$O35,0) -> 0 | ... AK37: =IFERROR(AK36*$O35,0) -> 0
B38: =IF($F38>$E$2,0,IF(E38<>"",MATCH(F39&" - Mapa",Orçamento!J:J,),0)) -> 0 | C38: =IF($D38>1,_xlfn.MAXIFS(Orçamento!G:G,Orçamento!J:J,F39&" - Mapa")+6-B38,0) -> 0 | D38: =IF($F38>$E$2,0,IF($G38=$E$6,$D$2,IF(E38<>"",_xlfn.MAXIFS(Orçamento!E:E,Orçamento!J:J,F39&" - Mapa"),0))) -> 0 | E38: =IF(F39="","",_xlfn.IFNA(MATCH($F39,'QC rev00'!$G$10:$G$120,),"")) | F38: {=OFFSET(F38,-3,,,)+1} -> 6 | G38: {=IF($F38>$E$2,"",IF($F$2=1,INDEX('QC rev00'!$M$10:$T$120,$F40,2),IF($F$2=2,INDEX(#REF!,$F40,2),INDEX(#REF!,$F40,2))))} | H38: {=IF($F38>$E$2,"",IF($F$2=1,INDEX('QC rev00'!$M$10:$T$120,$F40,3),IF($F$2=2,INDEX(#REF!,$F40,3),INDEX(#REF!,$F40,3))))} | L38: {=IF($F38>$E$2,"",IF($F$2=1,INDEX('QC rev00'!$M$10:$T$120,$F40,7),IF($F$2=2,INDEX(#REF!,$F40,7),INDEX(#REF!,$F40,7))))} | M38: {=IF($F38>$E$2,"",IF($F$2=1,INDEX('QC rev00'!$M$10:$T$120,$F40,8),IF($F$2=2,INDEX(#REF!,$F40,8),INDEX(#REF!,$F40,8))))} | N38: {=IF($F38>$E$2,0,IF(_xlfn.IFNA(MATCH($G38,Listas!$E$4:$E$206,),0)>0,$F$5,IF($F$2=1,INDEX('QC rev00'!$M$10:$U$120,$F40,9),IF($F$2=2,INDEX(#REF!,$F40,9),INDEX(#REF!,$F40,9)))))} -> 0 | O38: {=IF($F38>$E$2,0,IF(_xlfn.IFNA(MATCH($G38,Listas!$E$4:$E$206,),0)>0,1,IF($H$10=0,0,IF($F$2=1,INDEX('QC rev00'!$M$10:$BC$120,$F40,9+$F$3),IF($F$2=2,INDEX(#REF!,$F40,9+$F$3),INDEX(#REF!,$F40,9+$F$3)))*IF($E$5="X",1,1-$B40-$C40))))} -> 0 | P38: =N38*O38 -> 0 | Q38: IP | R38: {=IF($D38=0,"",IF($G38=$E$6,INDEX(Orçamento!$U:$U,MATCH(R$21,Orçamento!$C:$C,),1),INDEX(Orçamento!$U:$U,$B38,1)))} | S38: =IF(S$21>$D38,"",IF($G38=$E$6,INDEX(Orçamento!$U:$U,MATCH(S$21,Orçamento!$C:$C,),1),INDEX(Orçamento!$U:$U,MATCH(S$21&"-"&$F39,Orçamento!$F:$F,),1))) | T38: =IF(T$21>$D38,"",IF($G38=$E$6,INDEX(Orçamento!$U:$U,MATCH(T$21,Orçamento!$C:$C,),1),INDEX(Orçamento!$U:$U,MATCH(T$21&"-"&$F39,Orçamento!$F:$F,),1))) | U38: =IF(U$21>$D38,"",IF($G38=$E$6,INDEX(Orçamento!$U:$U,MATCH(U$21,Orçamento!$C:$C,),1),INDEX(Orçamento!$U:$U,MATCH(U$21&"-"&$F39,Orçamento!$F:$F,),1))) | V38: =IF(V$21>$D38,"",IF($G38=$E$6,INDEX(Orçamento!$U:$U,MATCH(V$21,Orçamento!$C:$C,),1),INDEX(Orçamento!$U:$U,MATCH(V$21&"-"&$F39,Orçamento!$F:$F,),1))) | W38: =IF(W$21>$D38,"",IF($G38=$E$6,INDEX(Orçamento!$U:$U,MATCH(W$21,Orçamento!$C:$C,),1),INDEX(Orçamento!$U:$U,MATCH(W$21&"-"&$F39,Orçamento!$F:$F,),1))) | X38: =IF(X$21>$D38,"",IF($G38=$E$6,INDEX(Orçamento!$U:$U,MATCH(X$21,Orçamento!$C:$C,),1),INDEX(Orçamento!$U:$U,MATCH(X$21&"-"&$F39,Orçamento!$F:$F,),1))) | Y38: =IF(Y$21>$D38,"",IF($G38=$E$6,INDEX(Orçamento!$U:$U,MATCH(Y$21,Orçamento!$C:$C,),1),INDEX(Orçamento!$U:$U,MATCH(Y$21&"-"&$F39,Orçamento!$F:$F,),1))) | Z38: =IF(Z$21>$D38,"",IF($G38=$E$6,INDEX(Orçamento!$U:$U,MATCH(Z$21,Orçamento!$C:$C,),1),INDEX(Orçamento!$U:$U,MATCH(Z$21&"-"&$F39,Orçamento!$F:$F,),1))) | ... AK38: =IF(AK$21>$D38,"",IF($G38=$E$6,INDEX(Orçamento!$U:$U,MATCH(AK$21,Orçamento!$C:$C,),1),INDEX(Orçamento!$U:$U,MATCH(AK$21&"-"&$F39,Orçamento!$F:$F,),1)))
